Workbook

Sheet DATASHEET
A1: TANGGAL | B1: CO | C1: NO2 | D1: O3 | E1: PM10 | F1: PM2.5 | G1: SO2 | H1: SEPEDA MOTOR | I1: MOBIL PRIBADI | J1: BIS/TRUCK BARANG
A2: 45337 | B2: 1 | C2: 20 | D2: 29.75 | E2: 13.76 | F2: 14.02 | G2: 39.89 | H2: 148384 | I2: 55102 | J2: 21131
A3: 45338 | B3: 1.49 | C3: 6.93 | D3: 19.78 | E3: 15.49 | F3: 15.18 | G3: 44.29 | H3: 161673 | I3: 60396 | J3: 26323
A4: 45342 | B4: 0.81 | C4: 13.53 | D4: 28.29 | E4: 16.67 | F4: 17.17 | G4: 18.2 | H4: 165764 | I4: 60934 | J4: 26548
A5: 45343 | B5: 1.39 | C5: 23.55 | D5: 22.96 | E5: 11.09 | F5: 15.05 | G5: 68.34 | H5: 143283 | I5: 54033 | J5: 26256
A6: 45344 | B6: 1.47 | C6: 113 | D6: 4.23 | E6: 2.04 | F6: 2.77 | G6: 81 | H6: 184188 | I6: 63106 | J6: 26807
A7: 45372 | B7: 1.12 | C7: 23.83 | D7: 43.46 | E7: 19.5 | F7: 19 | G7: 18.69 | H7: 185771 | I7: 59183 | J7: 25106
A8: 45373 | B8: 1.25 | C8: 26.63 | D8: 48.8 | E8: 29.73 | F8: 29.29 | G8: 21.42 | H8: 172673 | I8: 61134 | J8: 23582
A9: 45377 | B9: 1.12 | C9: 26.06 | D9: 49.67 | E9: 19.3 | F9: 19 | G9: 17.46 | H9: 171563 | I9: 60161 | J9: 26248
A10: 45383 | B10: 1.06 | C10: 25.42 | D10: 39.67 | E10: 11.58 | F10: 11.1 | G10: 20.17 | H10: 185013 | I10: 69963 | J10: 26633
A11: 45384 | B11: 1.17 | C11: 26.18 | D11: 39.47 | E11: 12.55 | F11: 12.07 | G11: 24.49 | H11: 148613 | I11: 57298 | J11: 25567
A12: 45385 | B12: 1.14 | C12: 26.15 | D12: 42.61 | E12: 16.45 | F12: 16.38 | G12: 22.4 | H12: 185635 | I12: 66703 | J12: 27783
A13: 45386 | B13: 1.1 | C13: 26.41 | D13: 46.31 | E13: 14 | F13: 13.67 | G13: 19.25 | H13: 162905 | I13: 66811 | J13: 32650
A14: 45387 | B14: 1.07 | C14: 24.06 | D14: 43.19 | E14: 13.08 | F14: 12.56 | G14: 18.29 | H14: 185156 | I14: 77105 | J14: 25781
A15: 45388 | B15: 1.09 | C15: 24.24 | D15: 39.46 | E15: 15.4 | F15: 14.82 | G15: 18.37 | H15: 132394 | I15: 65332 | J15: 26447
A16: 45389 | B16: 1.19 | C16: 25.24 | D16: 41.92 | E16: 20.3 | F16: 19.88 | G16: 23.53 | H16: 131300 | I16: 73922 | J16: 20660
A17: 45390 | B17: 1.31 | C17: 25.37 | D17: 39.29 | E17: 19.64 | F17: 19.2 | G17: 32.15 | H17: 138682 | I17: 75842 | J17: 26904
A18: 45391 | B18: 1.22 | C18: 26.46 | D18: 38.47 | E18: 17.44 | F18: 17.28 | G18: 28.79 | H18: 145227 | I18: 69217 | J18: 15346
A19: 45392 | B19: 1.22 | C19: 26.31 | D19: 35.58 | E19: 13.62 | F19: 13.19 | G19: 29.24 | H19: 83315 | I19: 70686 | J19: 17916
A20: 45393 | B20: 1.22 | C20: 27.12 | D20: 34.45 | E20: 10.05 | F20: 9.57 | G20: 29.65 | H20: 96864 | I20: 80354 | J20: 18746
A21: 45394 | B21: 1.15 | C21: 27.51 | D21: 34.13 | E21: 11.39 | F21: 11.07 | G21: 25.38 | H21: 136910 | I21: 72175 | J21: 14803
A22: 45395 | B22: 1.3 | C22: 27 | D22: 39.24 | E22: 17.22 | F22: 16.87 | G22: 31.71 | H22: 116389 | I22: 82775 | J22: 25296
A23: 45396 | B23: 1.29 | C23: 27.47 | D23: 39.63 | E23: 17.39 | F23: 17.84 | G23: 31.51 | H23: 136340 | I23: 84449 | J23: 21273
A24: 45397 | B24: 1.22 | C24: 27.38 | D24: 40.98 | E24: 18.45 | F24: 18.48 | G24: 23.68 | H24: 161911 | I24: 77932 | J24: 22331
A25: 45398 | B25: 1.1 | C25: 26.62 | D25: 43.81 | E25: 19.44 | F25: 19.71 | G25: 19.13 | H25: 173055 | I25: 71573 | J25: 26832
A26: 45399 | B26: 1.05 | C26: 25.3 | D26: 38.75 | E26: 13.72 | F26: 13.86 | G26: 18.07 | H26: 136714 | I26: 64963 | J26: 27918
A27: 45400 | B27: 1.18 | C27: 27.06 | D27: 37.17 | E27: 16.42 | F27: 15.8 | G27: 21.42 | H27: 158986 | I27: 65700 | J27: 23944
A28: 45401 | B28: 1.19 | C28: 27.08 | D28: 35.1 | E28: 11.97 | F28: 11.38 | G28: 22.92 | H28: 154378 | I28: 65911 | J28: 28749
A29: 45402 | B29: 1.15 | C29: 27.11 | D29: 33.99 | E29: 16 | F29: 16.03 | G29: 23.14 | H29: 154000 | I29: 72316 | J29: 29668
A30: 45403 | B30: 1.22 | C30: 27.42 | D30: 38.65 | E30: 19.93 | F30: 19.78 | G30: 23.94 | H30: 120505 | I30: 69223 | J30: 19673
A31: 45404 | B31: 1.15 | C31: 27.25 | D31: 34.39 | E31: 13.23 | F31: 13.21 | G31: 22.14 | H31: 136653 | I31: 61731 | J31: 29105
A32: 45405 | B32: 1.12 | C32: 27.33 | D32: 38.57 | E32: 14.79 | F32: 14.8 | G32: 19.36 | H32: 179314 | I32: 67401 | J32: 21034
A33: 45406 | B33: 1.39 | C33: 27.01 | D33: 35.24 | E33: 29.46 | F33: 29.65 | G33: 36.53 | H33: 183023 | I33: 66596 | J33: 23649
A34: 45407 | B34: 1.23 | C34: 26.83 | D34: 41.18 | E34: 27.47 | F34: 28.45 | G34: 24.76 | H34: 180926 | I34: 66500 | J34: 22820
A35: 45408 | B35: 1.12 | C35: 26.4 | D35: 40.69 | E35: 21.1 | F35: 21.33 | G35: 16.84 | H35: 174082 | I35: 63860 | J35: 29455
A36: 45409 | B36: 1.04 | C36: 23.85 | D36: 42.77 | E36: 17.67 | F36: 17.57 | G36: 15.18 | H36: 141930 | I36: 65369 | J36: 30755
A37: 45410 | B37: 1.25 | C37: 26.03 | D37: 44.25 | E37: 29.48 | F37: 28.6 | G37: 22.69 | H37: 132903 | I37: 67298 | J37: 26758
A38: 45411 | B38: 1.14 | C38: 25.84 | D38: 44.41 | E38: 26.41 | F38: 26.11 | G38: 19.32 | H38: 171608 | I38: 63485 | J38: 29197
A39: 45412 | B39: 1.2 | C39: 26.48 | D39: 42.43 | E39: 31.45 | F39: 31.49 | G39: 22.8 | H39: 189591 | I39: 67009 | J39: 26866
A40: 45413 | B40: 1.14 | C40: 26.56 | D40: 39.44 | E40: 30.47 | F40: 29.73 | G40: 22.35 | H40: 147924 | I40: 63815 | J40: 22068
...

Sheet CO
A1: date | B1: min | C1: max | D1: median | E1: q1 | F1: q3 | G1: stdev | H1: count | I1: cek
A2: 45337 | B2: 0.67 | C2: 1.47 | D2: 1 | E2: 0.76 | F2: 1.25 | G2: 0.263 | H2: 24 | I2: =AND(COUNTIF('NO2'!A:A,A2)>0,COUNTIF('O3'!A:A,A2)>0,COUNTIF('PM10'!A:A,A2)>0,COUNTIF('PM2.5'!A:A,A2)>0,COUNTIF('SO2'!A:A,A2)>0) -> TRUE
A3: 45338 | B3: 1.39 | C3: 1.63 | D3: 1.49 | E3: 1.43 | F3: 1.6 | G3: 0.084 | H3: 24 | I3: =AND(COUNTIF('NO2'!A:A,A3)>0,COUNTIF('O3'!A:A,A3)>0,COUNTIF('PM10'!A:A,A3)>0,COUNTIF('PM2.5'!A:A,A3)>0,COUNTIF('SO2'!A:A,A3)>0) -> TRUE
A4: 45342 | B4: 0.55 | C4: 1.2 | D4: 0.81 | E4: 0.62 | F4: 1.01 | G4: 0.213 | H4: 24 | I4: =AND(COUNTIF('NO2'!A:A,A4)>0,COUNTIF('O3'!A:A,A4)>0,COUNTIF('PM10'!A:A,A4)>0,COUNTIF('PM2.5'!A:A,A4)>0,COUNTIF('SO2'!A:A,A4)>0) -> TRUE
A5: 45343 | B5: 1.23 | C5: 1.44 | D5: 1.39 | E5: 1.37 | F5: 1.41 | G5: 0.049 | H5: 24 | I5: =AND(COUNTIF('NO2'!A:A,A5)>0,COUNTIF('O3'!A:A,A5)>0,COUNTIF('PM10'!A:A,A5)>0,COUNTIF('PM2.5'!A:A,A5)>0,COUNTIF('SO2'!A:A,A5)>0) -> TRUE
A6: 45344 | B6: 1.44 | C6: 1.47 | D6: 1.47 | E6: 1.46 | F6: 1.47 | G6: 0.008 | H6: 24 | I6: =AND(COUNTIF('NO2'!A:A,A6)>0,COUNTIF('O3'!A:A,A6)>0,COUNTIF('PM10'!A:A,A6)>0,COUNTIF('PM2.5'!A:A,A6)>0,COUNTIF('SO2'!A:A,A6)>0) -> TRUE
A7: 45372 | B7: 1.11 | C7: 1.12 | D7: 1.12 | E7: 1.12 | F7: 1.12 | G7: 0.006 | H7: 9 | I7: =AND(COUNTIF('NO2'!A:A,A7)>0,COUNTIF('O3'!A:A,A7)>0,COUNTIF('PM10'!A:A,A7)>0,COUNTIF('PM2.5'!A:A,A7)>0,COUNTIF('SO2'!A:A,A7)>0) -> TRUE
A8: 45373 | B8: 1.25 | C8: 1.25 | D8: 1.25 | E8: 1.25 | F8: 1.25 | G8: 0.002 | H8: 4 | I8: =AND(COUNTIF('NO2'!A:A,A8)>0,COUNTIF('O3'!A:A,A8)>0,COUNTIF('PM10'!A:A,A8)>0,COUNTIF('PM2.5'!A:A,A8)>0,COUNTIF('SO2'!A:A,A8)>0) -> TRUE
A9: 45377 | B9: 1.12 | C9: 1.12 | D9: 1.12 | E9: 1.12 | F9: 1.12 | G9: 0 | H9: 1 | I9: =AND(COUNTIF('NO2'!A:A,A9)>0,COUNTIF('O3'!A:A,A9)>0,COUNTIF('PM10'!A:A,A9)>0,COUNTIF('PM2.5'!A:A,A9)>0,COUNTIF('SO2'!A:A,A9)>0) -> TRUE
A10: 45383 | B10: 1.01 | C10: 1.12 | D10: 1.06 | E10: 1.03 | F10: 1.1 | G10: 0.037 | H10: 21 | I10: =AND(COUNTIF('NO2'!A:A,A10)>0,COUNTIF('O3'!A:A,A10)>0,COUNTIF('PM10'!A:A,A10)>0,COUNTIF('PM2.5'!A:A,A10)>0,COUNTIF('SO2'!A:A,A10)>0) -> TRUE
A11: 45384 | B11: 1.13 | C11: 1.18 | D11: 1.17 | E11: 1.15 | F11: 1.17 | G11: 0.01 | H11: 24 | I11: =AND(COUNTIF('NO2'!A:A,A11)>0,COUNTIF('O3'!A:A,A11)>0,COUNTIF('PM10'!A:A,A11)>0,COUNTIF('PM2.5'!A:A,A11)>0,COUNTIF('SO2'!A:A,A11)>0) -> TRUE
A12: 45385 | B12: 1.12 | C12: 1.15 | D12: 1.14 | E12: 1.12 | F12: 1.14 | G12: 0.01 | H12: 24 | I12: =AND(COUNTIF('NO2'!A:A,A12)>0,COUNTIF('O3'!A:A,A12)>0,COUNTIF('PM10'!A:A,A12)>0,COUNTIF('PM2.5'!A:A,A12)>0,COUNTIF('SO2'!A:A,A12)>0) -> TRUE
A13: 45386 | B13: 1.08 | C13: 1.12 | D13: 1.1 | E13: 1.08 | F13: 1.12 | G13: 0.015 | H13: 24 | I13: =AND(COUNTIF('NO2'!A:A,A13)>0,COUNTIF('O3'!A:A,A13)>0,COUNTIF('PM10'!A:A,A13)>0,COUNTIF('PM2.5'!A:A,A13)>0,COUNTIF('SO2'!A:A,A13)>0) -> TRUE
A14: 45387 | B14: 1.06 | C14: 1.09 | D14: 1.07 | E14: 1.06 | F14: 1.09 | G14: 0.012 | H14: 23 | I14: =AND(COUNTIF('NO2'!A:A,A14)>0,COUNTIF('O3'!A:A,A14)>0,COUNTIF('PM10'!A:A,A14)>0,COUNTIF('PM2.5'!A:A,A14)>0,COUNTIF('SO2'!A:A,A14)>0) -> TRUE
A15: 45388 | B15: 1.08 | C15: 1.13 | D15: 1.09 | E15: 1.08 | F15: 1.11 | G15: 0.017 | H15: 24 | I15: =AND(COUNTIF('NO2'!A:A,A15)>0,COUNTIF('O3'!A:A,A15)>0,COUNTIF('PM10'!A:A,A15)>0,COUNTIF('PM2.5'!A:A,A15)>0,COUNTIF('SO2'!A:A,A15)>0) -> TRUE
A16: 45389 | B16: 1.14 | C16: 1.37 | D16: 1.19 | E16: 1.17 | F16: 1.32 | G16: 0.078 | H16: 24 | I16: =AND(COUNTIF('NO2'!A:A,A16)>0,COUNTIF('O3'!A:A,A16)>0,COUNTIF('PM10'!A:A,A16)>0,COUNTIF('PM2.5'!A:A,A16)>0,COUNTIF('SO2'!A:A,A16)>0) -> TRUE
A17: 45390 | B17: 1.18 | C17: 1.34 | D17: 1.31 | E17: 1.23 | F17: 1.32 | G17: 0.058 | H17: 24 | I17: =AND(COUNTIF('NO2'!A:A,A17)>0,COUNTIF('O3'!A:A,A17)>0,COUNTIF('PM10'!A:A,A17)>0,COUNTIF('PM2.5'!A:A,A17)>0,COUNTIF('SO2'!A:A,A17)>0) -> TRUE
A18: 45391 | B18: 1.19 | C18: 1.25 | D18: 1.22 | E18: 1.2 | F18: 1.24 | G18: 0.022 | H18: 24 | I18: =AND(COUNTIF('NO2'!A:A,A18)>0,COUNTIF('O3'!A:A,A18)>0,COUNTIF('PM10'!A:A,A18)>0,COUNTIF('PM2.5'!A:A,A18)>0,COUNTIF('SO2'!A:A,A18)>0) -> TRUE
A19: 45392 | B19: 1.15 | C19: 1.25 | D19: 1.22 | E19: 1.19 | F19: 1.24 | G19: 0.031 | H19: 24 | I19: =AND(COUNTIF('NO2'!A:A,A19)>0,COUNTIF('O3'!A:A,A19)>0,COUNTIF('PM10'!A:A,A19)>0,COUNTIF('PM2.5'!A:A,A19)>0,COUNTIF('SO2'!A:A,A19)>0) -> TRUE
A20: 45393 | B20: 1.11 | C20: 1.24 | D20: 1.22 | E20: 1.14 | F20: 1.23 | G20: 0.045 | H20: 24 | I20: =AND(COUNTIF('NO2'!A:A,A20)>0,COUNTIF('O3'!A:A,A20)>0,COUNTIF('PM10'!A:A,A20)>0,COUNTIF('PM2.5'!A:A,A20)>0,COUNTIF('SO2'!A:A,A20)>0) -> TRUE
A21: 45394 | B21: 1.11 | C21: 1.34 | D21: 1.15 | E21: 1.11 | F21: 1.26 | G21: 0.081 | H21: 24 | I21: =AND(COUNTIF('NO2'!A:A,A21)>0,COUNTIF('O3'!A:A,A21)>0,COUNTIF('PM10'!A:A,A21)>0,COUNTIF('PM2.5'!A:A,A21)>0,COUNTIF('SO2'!A:A,A21)>0) -> TRUE
... A100: 45483 | B100: 1.25 | C100: 1.28 | D100: 1.27 | E100: 1.26 | F100: 1.27 | G100: 0.008 | H100: 15 | I100: =AND(COUNTIF('NO2'!A:A,A100)>0,COUNTIF('O3'!A:A,A100)>0,COUNTIF('PM10'!A:A,A100)>0,COUNTIF('PM2.5'!A:A,A100)>0,COUNTIF('SO2'!A:A,A100)>0) -> TRUE
A101: 45484 | B101: 0.83 | C101: 0.83 | D101: 0.83 | E101: 0.83 | F101: 0.83 | G101: 0 | H101: 1 | I101: =AND(COUNTIF('NO2'!A:A,A101)>0,COUNTIF('O3'!A:A,A101)>0,COUNTIF('PM10'!A:A,A101)>0,COUNTIF('PM2.5'!A:A,A101)>0,COUNTIF('SO2'!A:A,A101)>0) -> TRUE
A102: 45485 | B102: 0.81 | C102: 0.83 | D102: 0.82 | E102: 0.81 | F102: 0.82 | G102: 0.005 | H102: 24 | I102: =AND(COUNTIF('NO2'!A:A,A102)>0,COUNTIF('O3'!A:A,A102)>0,COUNTIF('PM10'!A:A,A102)>0,COUNTIF('PM2.5'!A:A,A102)>0,COUNTIF('SO2'!A:A,A102)>0) -> TRUE
A103: 45486 | B103: 0.79 | C103: 0.82 | D103: 0.81 | E103: 0.81 | F103: 0.82 | G103: 0.007 | H103: 24 | I103: =AND(COUNTIF('NO2'!A:A,A103)>0,COUNTIF('O3'!A:A,A103)>0,COUNTIF('PM10'!A:A,A103)>0,COUNTIF('PM2.5'!A:A,A103)>0,COUNTIF('SO2'!A:A,A103)>0) -> TRUE
A104: 45487 | B104: 0.77 | C104: 0.79 | D104: 0.78 | E104: 0.77 | F104: 0.79 | G104: 0.007 | H104: 24 | I104: =AND(COUNTIF('NO2'!A:A,A104)>0,COUNTIF('O3'!A:A,A104)>0,COUNTIF('PM10'!A:A,A104)>0,COUNTIF('PM2.5'!A:A,A104)>0,COUNTIF('SO2'!A:A,A104)>0) -> TRUE
A105: 45488 | B105: 0.79 | C105: 0.82 | D105: 0.8 | E105: 0.8 | F105: 0.81 | G105: 0.008 | H105: 24 | I105: =AND(COUNTIF('NO2'!A:A,A105)>0,COUNTIF('O3'!A:A,A105)>0,COUNTIF('PM10'!A:A,A105)>0,COUNTIF('PM2.5'!A:A,A105)>0,COUNTIF('SO2'!A:A,A105)>0) -> TRUE
A106: 45489 | B106: 0.79 | C106: 0.82 | D106: 0.79 | E106: 0.79 | F106: 0.8 | G106: 0.011 | H106: 24 | I106: =AND(COUNTIF('NO2'!A:A,A106)>0,COUNTIF('O3'!A:A,A106)>0,COUNTIF('PM10'!A:A,A106)>0,COUNTIF('PM2.5'!A:A,A106)>0,COUNTIF('SO2'!A:A,A106)>0) -> TRUE
A107: 45490 | B107: 0.82 | C107: 0.86 | D107: 0.83 | E107: 0.83 | F107: 0.83 | G107: 0.009 | H107: 24 | I107: =AND(COUNTIF('NO2'!A:A,A107)>0,COUNTIF('O3'!A:A,A107)>0,COUNTIF('PM10'!A:A,A107)>0,COUNTIF('PM2.5'!A:A,A107)>0,COUNTIF('SO2'!A:A,A107)>0) -> TRUE
A108: 45491 | B108: 0.86 | C108: 0.87 | D108: 0.87 | E108: 0.86 | F108: 0.87 | G108: 0.007 | H108: 24 | I108: =AND(COUNTIF('NO2'!A:A,A108)>0,COUNTIF('O3'!A:A,A108)>0,COUNTIF('PM10'!A:A,A108)>0,COUNTIF('PM2.5'!A:A,A108)>0,COUNTIF('SO2'!A:A,A108)>0) -> TRUE
A109: 45492 | B109: 0.83 | C109: 0.85 | D109: 0.84 | E109: 0.83 | F109: 0.85 | G109: 0.007 | H109: 24 | I109: =AND(COUNTIF('NO2'!A:A,A109)>0,COUNTIF('O3'!A:A,A109)>0,COUNTIF('PM10'!A:A,A109)>0,COUNTIF('PM2.5'!A:A,A109)>0,COUNTIF('SO2'!A:A,A109)>0) -> TRUE
A110: 45493 | B110: 0.81 | C110: 0.84 | D110: 0.83 | E110: 0.83 | F110: 0.84 | G110: 0.01 | H110: 24 | I110: =AND(COUNTIF('NO2'!A:A,A110)>0,COUNTIF('O3'!A:A,A110)>0,COUNTIF('PM10'!A:A,A110)>0,COUNTIF('PM2.5'!A:A,A110)>0,COUNTIF('SO2'!A:A,A110)>0) -> TRUE
A111: 45494 | B111: 0.78 | C111: 0.81 | D111: 0.8 | E111: 0.8 | F111: 0.81 | G111: 0.007 | H111: 23 | I111: =AND(COUNTIF('NO2'!A:A,A111)>0,COUNTIF('O3'!A:A,A111)>0,COUNTIF('PM10'!A:A,A111)>0,COUNTIF('PM2.5'!A:A,A111)>0,COUNTIF('SO2'!A:A,A111)>0) -> TRUE
A112: 45495 | B112: 0.78 | C112: 0.81 | D112: 0.8 | E112: 0.78 | F112: 0.8 | G112: 0.009 | H112: 24 | I112: =AND(COUNTIF('NO2'!A:A,A112)>0,COUNTIF('O3'!A:A,A112)>0,COUNTIF('PM10'!A:A,A112)>0,COUNTIF('PM2.5'!A:A,A112)>0,COUNTIF('SO2'!A:A,A112)>0) -> TRUE
A113: 45496 | B113: 0.8 | C113: 0.81 | D113: 0.8 | E113: 0.8 | F113: 0.81 | G113: 0.002 | H113: 24 | I113: =AND(COUNTIF('NO2'!A:A,A113)>0,COUNTIF('O3'!A:A,A113)>0,COUNTIF('PM10'!A:A,A113)>0,COUNTIF('PM2.5'!A:A,A113)>0,COUNTIF('SO2'!A:A,A113)>0) -> TRUE
... A132: 45516 | B132: 0.16 | C132: 0.63 | D132: 0.21 | E132: 0.16 | F132: 0.45 | G132: 0.164 | H132: 17 | I132: =AND(COUNTIF('NO2'!A:A,A132)>0,COUNTIF('O3'!A:A,A132)>0,COUNTIF('PM10'!A:A,A132)>0,COUNTIF('PM2.5'!A:A,A132)>0,COUNTIF('SO2'!A:A,A132)>0) -> TRUE
A133: 45517 | B133: 0.99 | C133: 1.01 | D133: 1.01 | E133: 1 | F133: 1.01 | G133: 0.008 | H133: 5 | I133: =AND(COUNTIF('NO2'!A:A,A133)>0,COUNTIF('O3'!A:A,A133)>0,COUNTIF('PM10'!A:A,A133)>0,COUNTIF('PM2.5'!A:A,A133)>0,COUNTIF('SO2'!A:A,A133)>0) -> TRUE
A134: 45518 | B134: 0.94 | C134: 0.99 | D134: 0.98 | E134: 0.95 | F134: 0.98 | G134: 0.014 | H134: 24 | I134: =AND(COUNTIF('NO2'!A:A,A134)>0,COUNTIF('O3'!A:A,A134)>0,COUNTIF('PM10'!A:A,A134)>0,COUNTIF('PM2.5'!A:A,A134)>0,COUNTIF('SO2'!A:A,A134)>0) -> TRUE
A135: 45519 | B135: 0.92 | C135: 0.94 | D135: 0.93 | E135: 0.92 | F135: 0.94 | G135: 0.007 | H135: 15 | I135: =AND(COUNTIF('NO2'!A:A,A135)>0,COUNTIF('O3'!A:A,A135)>0,COUNTIF('PM10'!A:A,A135)>0,COUNTIF('PM2.5'!A:A,A135)>0,COUNTIF('SO2'!A:A,A135)>0) -> TRUE
A136: 45521 | B136: 1.2 | C136: 1.2 | D136: 1.2 | E136: 1.2 | F136: 1.2 | G136: 0.001 | H136: 24 | I136: =AND(COUNTIF('NO2'!A:A,A136)>0,COUNTIF('O3'!A:A,A136)>0,COUNTIF('PM10'!A:A,A136)>0,COUNTIF('PM2.5'!A:A,A136)>0,COUNTIF('SO2'!A:A,A136)>0) -> TRUE
...

Sheet NO2
A1: date | B1: min | C1: max | D1: median | E1: q1 | F1: q3 | G1: stdev | H1: count | I1: cek
A2: 45337 | B2: 10.48 | C2: 86.5 | D2: 20 | E2: 13.53 | F2: 38.4 | G2: 19255 | H2: 20 | I2: =AND(COUNTIF(CO!A:A,A2)>0,COUNTIF('O3'!A:A,A2)>0,COUNTIF('PM10'!A:A,A2)>0,COUNTIF('PM2.5'!A:A,A2)>0,COUNTIF('SO2'!A:A,A2)>0,COUNTIF(Kendaraan!A:A,A2)) -> TRUE
A3: 45338 | B3: 1.25 | C3: 9.98 | D3: 6.93 | E3: 3.26 | F3: 9.32 | G3: 3235 | H3: 8 | I3: =AND(COUNTIF(CO!A:A,A3)>0,COUNTIF('O3'!A:A,A3)>0,COUNTIF('PM10'!A:A,A3)>0,COUNTIF('PM2.5'!A:A,A3)>0,COUNTIF('SO2'!A:A,A3)>0,COUNTIF(Kendaraan!A:A,A3)) -> TRUE
A4: 45342 | B4: 6.95 | C4: 61 | D4: 13.53 | E4: 8.86 | F4: 28.56 | G4: 17387 | H4: 19 | I4: =AND(COUNTIF(CO!A:A,A4)>0,COUNTIF('O3'!A:A,A4)>0,COUNTIF('PM10'!A:A,A4)>0,COUNTIF('PM2.5'!A:A,A4)>0,COUNTIF('SO2'!A:A,A4)>0,COUNTIF(Kendaraan!A:A,A4)) -> TRUE
A5: 45343 | B5: 1.6 | C5: 77.69 | D5: 23.55 | E5: 6.13 | F5: 51.8 | G5: 25091 | H5: 24 | I5: =AND(COUNTIF(CO!A:A,A5)>0,COUNTIF('O3'!A:A,A5)>0,COUNTIF('PM10'!A:A,A5)>0,COUNTIF('PM2.5'!A:A,A5)>0,COUNTIF('SO2'!A:A,A5)>0,COUNTIF(Kendaraan!A:A,A5)) -> TRUE
A6: 45344 | B6: 82.4 | C6: 113 | D6: 113 | E6: 108.3 | F6: 113 | G6: 9054 | H6: 24 | I6: =AND(COUNTIF(CO!A:A,A6)>0,COUNTIF('O3'!A:A,A6)>0,COUNTIF('PM10'!A:A,A6)>0,COUNTIF('PM2.5'!A:A,A6)>0,COUNTIF('SO2'!A:A,A6)>0,COUNTIF(Kendaraan!A:A,A6)) -> TRUE
A7: 45372 | B7: 22.75 | C7: 24.48 | D7: 23.83 | E7: 23.1 | F7: 24.31 | G7: 0.595 | H7: 9 | I7: =AND(COUNTIF(CO!A:A,A7)>0,COUNTIF('O3'!A:A,A7)>0,COUNTIF('PM10'!A:A,A7)>0,COUNTIF('PM2.5'!A:A,A7)>0,COUNTIF('SO2'!A:A,A7)>0,COUNTIF(Kendaraan!A:A,A7)) -> TRUE
A8: 45373 | B8: 26.48 | C8: 26.79 | D8: 26.63 | E8: 26.52 | F8: 26.74 | G8: 0.119 | H8: 4 | I8: =AND(COUNTIF(CO!A:A,A8)>0,COUNTIF('O3'!A:A,A8)>0,COUNTIF('PM10'!A:A,A8)>0,COUNTIF('PM2.5'!A:A,A8)>0,COUNTIF('SO2'!A:A,A8)>0,COUNTIF(Kendaraan!A:A,A8)) -> TRUE
A9: 45377 | B9: 26.06 | C9: 26.06 | D9: 26.06 | E9: 26.06 | F9: 26.06 | G9: 0 | H9: 1 | I9: =AND(COUNTIF(CO!A:A,A9)>0,COUNTIF('O3'!A:A,A9)>0,COUNTIF('PM10'!A:A,A9)>0,COUNTIF('PM2.5'!A:A,A9)>0,COUNTIF('SO2'!A:A,A9)>0,COUNTIF(Kendaraan!A:A,A9)) -> TRUE
A10: 45383 | B10: 23.79 | C10: 26.17 | D10: 25.42 | E10: 24.55 | F10: 25.66 | G10: 0.704 | H10: 21 | I10: =AND(COUNTIF(CO!A:A,A10)>0,COUNTIF('O3'!A:A,A10)>0,COUNTIF('PM10'!A:A,A10)>0,COUNTIF('PM2.5'!A:A,A10)>0,COUNTIF('SO2'!A:A,A10)>0,COUNTIF(Kendaraan!A:A,A10)) -> TRUE
A11: 45384 | B11: 25.65 | C11: 26.56 | D11: 26.18 | E11: 25.97 | F11: 26.38 | G11: 0.268 | H11: 24 | I11: =AND(COUNTIF(CO!A:A,A11)>0,COUNTIF('O3'!A:A,A11)>0,COUNTIF('PM10'!A:A,A11)>0,COUNTIF('PM2.5'!A:A,A11)>0,COUNTIF('SO2'!A:A,A11)>0,COUNTIF(Kendaraan!A:A,A11)) -> TRUE
A12: 45385 | B12: 25.48 | C12: 26.65 | D12: 26.15 | E12: 25.69 | F12: 26.44 | G12: 0.392 | H12: 24 | I12: =AND(COUNTIF(CO!A:A,A12)>0,COUNTIF('O3'!A:A,A12)>0,COUNTIF('PM10'!A:A,A12)>0,COUNTIF('PM2.5'!A:A,A12)>0,COUNTIF('SO2'!A:A,A12)>0,COUNTIF(Kendaraan!A:A,A12)) -> TRUE
A13: 45386 | B13: 26.15 | C13: 26.88 | D13: 26.41 | E13: 26.25 | F13: 26.74 | G13: 0.249 | H13: 24 | I13: =AND(COUNTIF(CO!A:A,A13)>0,COUNTIF('O3'!A:A,A13)>0,COUNTIF('PM10'!A:A,A13)>0,COUNTIF('PM2.5'!A:A,A13)>0,COUNTIF('SO2'!A:A,A13)>0,COUNTIF(Kendaraan!A:A,A13)) -> TRUE
A14: 45387 | B14: 23.17 | C14: 26.12 | D14: 24.06 | E14: 23.71 | F14: 25.1 | G14: 0.864 | H14: 23 | I14: =AND(COUNTIF(CO!A:A,A14)>0,COUNTIF('O3'!A:A,A14)>0,COUNTIF('PM10'!A:A,A14)>0,COUNTIF('PM2.5'!A:A,A14)>0,COUNTIF('SO2'!A:A,A14)>0,COUNTIF(Kendaraan!A:A,A14)) -> TRUE
A15: 45388 | B15: 23 | C15: 24.73 | D15: 24.24 | E15: 23.29 | F15: 24.49 | G15: 0.583 | H15: 24 | I15: =AND(COUNTIF(CO!A:A,A15)>0,COUNTIF('O3'!A:A,A15)>0,COUNTIF('PM10'!A:A,A15)>0,COUNTIF('PM2.5'!A:A,A15)>0,COUNTIF('SO2'!A:A,A15)>0,COUNTIF(Kendaraan!A:A,A15)) -> TRUE
A16: 45389 | B16: 24.94 | C16: 25.79 | D16: 25.24 | E16: 25.12 | F16: 25.62 | G16: 0.277 | H16: 24 | I16: =AND(COUNTIF(CO!A:A,A16)>0,COUNTIF('O3'!A:A,A16)>0,COUNTIF('PM10'!A:A,A16)>0,COUNTIF('PM2.5'!A:A,A16)>0,COUNTIF('SO2'!A:A,A16)>0,COUNTIF(Kendaraan!A:A,A16)) -> TRUE
A17: 45390 | B17: 25.06 | C17: 25.62 | D17: 25.37 | E17: 25.21 | F17: 25.51 | G17: 0.171 | H17: 24 | I17: =AND(COUNTIF(CO!A:A,A17)>0,COUNTIF('O3'!A:A,A17)>0,COUNTIF('PM10'!A:A,A17)>0,COUNTIF('PM2.5'!A:A,A17)>0,COUNTIF('SO2'!A:A,A17)>0,COUNTIF(Kendaraan!A:A,A17)) -> TRUE
A18: 45391 | B18: 25.44 | C18: 26.75 | D18: 26.46 | E18: 26.04 | F18: 26.61 | G18: 0.376 | H18: 24 | I18: =AND(COUNTIF(CO!A:A,A18)>0,COUNTIF('O3'!A:A,A18)>0,COUNTIF('PM10'!A:A,A18)>0,COUNTIF('PM2.5'!A:A,A18)>0,COUNTIF('SO2'!A:A,A18)>0,COUNTIF(Kendaraan!A:A,A18)) -> TRUE
A19: 45392 | B19: 26.15 | C19: 26.71 | D19: 26.31 | E19: 26.26 | F19: 26.33 | G19: 0.113 | H19: 24 | I19: =AND(COUNTIF(CO!A:A,A19)>0,COUNTIF('O3'!A:A,A19)>0,COUNTIF('PM10'!A:A,A19)>0,COUNTIF('PM2.5'!A:A,A19)>0,COUNTIF('SO2'!A:A,A19)>0,COUNTIF(Kendaraan!A:A,A19)) -> TRUE
A20: 45393 | B20: 26.35 | C20: 27.27 | D20: 27.12 | E20: 27.03 | F20: 27.19 | G20: 0.241 | H20: 24 | I20: =AND(COUNTIF(CO!A:A,A20)>0,COUNTIF('O3'!A:A,A20)>0,COUNTIF('PM10'!A:A,A20)>0,COUNTIF('PM2.5'!A:A,A20)>0,COUNTIF('SO2'!A:A,A20)>0,COUNTIF(Kendaraan!A:A,A20)) -> TRUE
A21: 45394 | B21: 27.25 | C21: 27.67 | D21: 27.51 | E21: 27.29 | F21: 27.6 | G21: 0.154 | H21: 24 | I21: =AND(COUNTIF(CO!A:A,A21)>0,COUNTIF('O3'!A:A,A21)>0,COUNTIF('PM10'!A:A,A21)>0,COUNTIF('PM2.5'!A:A,A21)>0,COUNTIF('SO2'!A:A,A21)>0,COUNTIF(Kendaraan!A:A,A21)) -> TRUE
A22: 45395 | B22: 26.9 | C22: 27.65 | D22: 27 | E22: 26.92 | F22: 27.2 | G22: 0.24 | H22: 24 | I22: =AND(COUNTIF(CO!A:A,A22)>0,COUNTIF('O3'!A:A,A22)>0,COUNTIF('PM10'!A:A,A22)>0,COUNTIF('PM2.5'!A:A,A22)>0,COUNTIF('SO2'!A:A,A22)>0,COUNTIF(Kendaraan!A:A,A22)) -> TRUE
A23: 45396 | B23: 27.02 | C23: 27.71 | D23: 27.47 | E23: 27.37 | F23: 27.65 | G23: 0.21 | H23: 24 | I23: =AND(COUNTIF(CO!A:A,A23)>0,COUNTIF('O3'!A:A,A23)>0,COUNTIF('PM10'!A:A,A23)>0,COUNTIF('PM2.5'!A:A,A23)>0,COUNTIF('SO2'!A:A,A23)>0,COUNTIF(Kendaraan!A:A,A23)) -> TRUE
A24: 45397 | B24: 27.21 | C24: 27.46 | D24: 27.38 | E24: 27.31 | F24: 27.42 | G24: 0.074 | H24: 24 | I24: =AND(COUNTIF(CO!A:A,A24)>0,COUNTIF('O3'!A:A,A24)>0,COUNTIF('PM10'!A:A,A24)>0,COUNTIF('PM2.5'!A:A,A24)>0,COUNTIF('SO2'!A:A,A24)>0,COUNTIF(Kendaraan!A:A,A24)) -> TRUE
A25: 45398 | B25: 25.58 | C25: 27.31 | D25: 26.62 | E25: 26.13 | F25: 26.87 | G25: 0.497 | H25: 24 | I25: =AND(COUNTIF(CO!A:A,A25)>0,COUNTIF('O3'!A:A,A25)>0,COUNTIF('PM10'!A:A,A25)>0,COUNTIF('PM2.5'!A:A,A25)>0,COUNTIF('SO2'!A:A,A25)>0,COUNTIF(Kendaraan!A:A,A25)) -> TRUE
A26: 45399 | B26: 25.04 | C26: 25.75 | D26: 25.3 | E26: 25.11 | F26: 25.48 | G26: 0.223 | H26: 24 | I26: =AND(COUNTIF(CO!A:A,A26)>0,COUNTIF('O3'!A:A,A26)>0,COUNTIF('PM10'!A:A,A26)>0,COUNTIF('PM2.5'!A:A,A26)>0,COUNTIF('SO2'!A:A,A26)>0,COUNTIF(Kendaraan!A:A,A26)) -> TRUE
A27: 45400 | B27: 25.79 | C27: 27.31 | D27: 27.06 | E27: 26.39 | F27: 27.22 | G27: 0.502 | H27: 24 | I27: =AND(COUNTIF(CO!A:A,A27)>0,COUNTIF('O3'!A:A,A27)>0,COUNTIF('PM10'!A:A,A27)>0,COUNTIF('PM2.5'!A:A,A27)>0,COUNTIF('SO2'!A:A,A27)>0,COUNTIF(Kendaraan!A:A,A27)) -> TRUE
A28: 45401 | B28: 26.96 | C28: 27.42 | D28: 27.08 | E28: 26.98 | F28: 27.32 | G28: 0.173 | H28: 24 | I28: =AND(COUNTIF(CO!A:A,A28)>0,COUNTIF('O3'!A:A,A28)>0,COUNTIF('PM10'!A:A,A28)>0,COUNTIF('PM2.5'!A:A,A28)>0,COUNTIF('SO2'!A:A,A28)>0,COUNTIF(Kendaraan!A:A,A28)) -> TRUE
A29: 45402 | B29: 27 | C29: 27.17 | D29: 27.11 | E29: 27.06 | F29: 27.12 | G29: 0.048 | H29: 24 | I29: =AND(COUNTIF(CO!A:A,A29)>0,COUNTIF('O3'!A:A,A29)>0,COUNTIF('PM10'!A:A,A29)>0,COUNTIF('PM2.5'!A:A,A29)>0,COUNTIF('SO2'!A:A,A29)>0,COUNTIF(Kendaraan!A:A,A29)) -> TRUE
A30: 45403 | B30: 27.04 | C30: 27.48 | D30: 27.42 | E30: 27.2 | F30: 27.44 | G30: 0.157 | H30: 24 | I30: =AND(COUNTIF(CO!A:A,A30)>0,COUNTIF('O3'!A:A,A30)>0,COUNTIF('PM10'!A:A,A30)>0,COUNTIF('PM2.5'!A:A,A30)>0,COUNTIF('SO2'!A:A,A30)>0,COUNTIF(Kendaraan!A:A,A30)) -> TRUE
A31: 45404 | B31: 27.15 | C31: 27.52 | D31: 27.25 | E31: 27.21 | F31: 27.39 | G31: 0.115 | H31: 24 | I31: =AND(COUNTIF(CO!A:A,A31)>0,COUNTIF('O3'!A:A,A31)>0,COUNTIF('PM10'!A:A,A31)>0,COUNTIF('PM2.5'!A:A,A31)>0,COUNTIF('SO2'!A:A,A31)>0,COUNTIF(Kendaraan!A:A,A31)) -> TRUE
A32: 45405 | B32: 27.19 | C32: 27.4 | D32: 27.33 | E32: 27.26 | F32: 27.38 | G32: 0.074 | H32: 24 | I32: =AND(COUNTIF(CO!A:A,A32)>0,COUNTIF('O3'!A:A,A32)>0,COUNTIF('PM10'!A:A,A32)>0,COUNTIF('PM2.5'!A:A,A32)>0,COUNTIF('SO2'!A:A,A32)>0,COUNTIF(Kendaraan!A:A,A32)) -> TRUE
A33: 45406 | B33: 26.75 | C33: 27.35 | D33: 27.01 | E33: 26.8 | F33: 27.17 | G33: 0.196 | H33: 24 | I33: =AND(COUNTIF(CO!A:A,A33)>0,COUNTIF('O3'!A:A,A33)>0,COUNTIF('PM10'!A:A,A33)>0,COUNTIF('PM2.5'!A:A,A33)>0,COUNTIF('SO2'!A:A,A33)>0,COUNTIF(Kendaraan!A:A,A33)) -> TRUE
A34: 45407 | B34: 26.71 | C34: 26.94 | D34: 26.83 | E34: 26.78 | F34: 26.87 | G34: 0.059 | H34: 24 | I34: =AND(COUNTIF(CO!A:A,A34)>0,COUNTIF('O3'!A:A,A34)>0,COUNTIF('PM10'!A:A,A34)>0,COUNTIF('PM2.5'!A:A,A34)>0,COUNTIF('SO2'!A:A,A34)>0,COUNTIF(Kendaraan!A:A,A34)) -> TRUE
A35: 45408 | B35: 25.04 | C35: 26.9 | D35: 26.4 | E35: 25.92 | F35: 26.73 | G35: 0.554 | H35: 24 | I35: =AND(COUNTIF(CO!A:A,A35)>0,COUNTIF('O3'!A:A,A35)>0,COUNTIF('PM10'!A:A,A35)>0,COUNTIF('PM2.5'!A:A,A35)>0,COUNTIF('SO2'!A:A,A35)>0,COUNTIF(Kendaraan!A:A,A35)) -> TRUE
A36: 45409 | B36: 23.42 | C36: 24.85 | D36: 23.85 | E36: 23.59 | F36: 24.31 | G36: 0.446 | H36: 24 | I36: =AND(COUNTIF(CO!A:A,A36)>0,COUNTIF('O3'!A:A,A36)>0,COUNTIF('PM10'!A:A,A36)>0,COUNTIF('PM2.5'!A:A,A36)>0,COUNTIF('SO2'!A:A,A36)>0,COUNTIF(Kendaraan!A:A,A36)) -> TRUE
A37: 45410 | B37: 24.81 | C37: 26.17 | D37: 26.03 | E37: 25.57 | F37: 26.15 | G37: 0.417 | H37: 24 | I37: =AND(COUNTIF(CO!A:A,A37)>0,COUNTIF('O3'!A:A,A37)>0,COUNTIF('PM10'!A:A,A37)>0,COUNTIF('PM2.5'!A:A,A37)>0,COUNTIF('SO2'!A:A,A37)>0,COUNTIF(Kendaraan!A:A,A37)) -> TRUE
A38: 45411 | B38: 25.73 | C38: 26.08 | D38: 25.84 | E38: 25.8 | F38: 25.93 | G38: 0.091 | H38: 24 | I38: =AND(COUNTIF(CO!A:A,A38)>0,COUNTIF('O3'!A:A,A38)>0,COUNTIF('PM10'!A:A,A38)>0,COUNTIF('PM2.5'!A:A,A38)>0,COUNTIF('SO2'!A:A,A38)>0,COUNTIF(Kendaraan!A:A,A38)) -> TRUE
A39: 45412 | B39: 26.21 | C39: 26.69 | D39: 26.48 | E39: 26.28 | F39: 26.64 | G39: 0.166 | H39: 24 | I39: =AND(COUNTIF(CO!A:A,A39)>0,COUNTIF('O3'!A:A,A39)>0,COUNTIF('PM10'!A:A,A39)>0,COUNTIF('PM2.5'!A:A,A39)>0,COUNTIF('SO2'!A:A,A39)>0,COUNTIF(Kendaraan!A:A,A39)) -> TRUE
A40: 45413 | B40: 26.46 | C40: 26.75 | D40: 26.56 | E40: 26.52 | F40: 26.61 | G40: 0.068 | H40: 24 | I40: =AND(COUNTIF(CO!A:A,A40)>0,COUNTIF('O3'!A:A,A40)>0,COUNTIF('PM10'!A:A,A40)>0,COUNTIF('PM2.5'!A:A,A40)>0,COUNTIF('SO2'!A:A,A40)>0,COUNTIF(Kendaraan!A:A,A40)) -> TRUE
...

Sheet O3
A1: date | B1: min | C1: max | D1: median | E1: q1 | F1: q3 | G1: stdev | H1: count | I1: cek
A2: 45337 | B2: 23 | C2: 32.61 | D2: 29.75 | E2: 28.11 | F2: 31.25 | G2: 2593 | H2: 24 | I2: =AND(COUNTIF(CO!A:A,A2)>0,COUNTIF('NO2'!A:A,A2)>0,COUNTIF('PM10'!A:A,A2)>0,COUNTIF('PM2.5'!A:A,A2)>0,COUNTIF('SO2'!A:A,A2)>0,COUNTIF(Kendaraan!A:A,A2)>0) -> TRUE
A3: 45338 | B3: 4.13 | C3: 33.11 | D3: 19.78 | E3: 11.74 | F3: 24.92 | G3: 8396 | H3: 24 | I3: =AND(COUNTIF(CO!A:A,A3)>0,COUNTIF('NO2'!A:A,A3)>0,COUNTIF('PM10'!A:A,A3)>0,COUNTIF('PM2.5'!A:A,A3)>0,COUNTIF('SO2'!A:A,A3)>0,COUNTIF(Kendaraan!A:A,A3)>0) -> TRUE
A4: 45342 | B4: 26.17 | C4: 43.5 | D4: 28.29 | E4: 27.79 | F4: 28.5 | G4: 3514 | H4: 19 | I4: =AND(COUNTIF(CO!A:A,A4)>0,COUNTIF('NO2'!A:A,A4)>0,COUNTIF('PM10'!A:A,A4)>0,COUNTIF('PM2.5'!A:A,A4)>0,COUNTIF('SO2'!A:A,A4)>0,COUNTIF(Kendaraan!A:A,A4)>0) -> TRUE
A5: 45343 | B5: 9.06 | C5: 28.65 | D5: 22.96 | E5: 15.7 | F5: 28.49 | G5: 6687 | H5: 24 | I5: =AND(COUNTIF(CO!A:A,A5)>0,COUNTIF('NO2'!A:A,A5)>0,COUNTIF('PM10'!A:A,A5)>0,COUNTIF('PM2.5'!A:A,A5)>0,COUNTIF('SO2'!A:A,A5)>0,COUNTIF(Kendaraan!A:A,A5)>0) -> TRUE
A6: 45344 | B6: 0.6 | C6: 7.85 | D6: 4.23 | E6: 1.81 | F6: 6.65 | G6: 2418 | H6: 7 | I6: =AND(COUNTIF(CO!A:A,A6)>0,COUNTIF('NO2'!A:A,A6)>0,COUNTIF('PM10'!A:A,A6)>0,COUNTIF('PM2.5'!A:A,A6)>0,COUNTIF('SO2'!A:A,A6)>0,COUNTIF(Kendaraan!A:A,A6)>0) -> TRUE
A7: 45372 | B7: 42.88 | C7: 43.58 | D7: 43.46 | E7: 43.11 | F7: 43.47 | G7: 0.221 | H7: 9 | I7: =AND(COUNTIF(CO!A:A,A7)>0,COUNTIF('NO2'!A:A,A7)>0,COUNTIF('PM10'!A:A,A7)>0,COUNTIF('PM2.5'!A:A,A7)>0,COUNTIF('SO2'!A:A,A7)>0,COUNTIF(Kendaraan!A:A,A7)>0) -> TRUE
A8: 45373 | B8: 48.77 | C8: 48.88 | D8: 48.8 | E8: 48.78 | F8: 48.85 | G8: 0.041 | H8: 4 | I8: =AND(COUNTIF(CO!A:A,A8)>0,COUNTIF('NO2'!A:A,A8)>0,COUNTIF('PM10'!A:A,A8)>0,COUNTIF('PM2.5'!A:A,A8)>0,COUNTIF('SO2'!A:A,A8)>0,COUNTIF(Kendaraan!A:A,A8)>0) -> TRUE
A9: 45377 | B9: 49.67 | C9: 49.67 | D9: 49.67 | E9: 49.67 | F9: 49.67 | G9: 0 | H9: 1 | I9: =AND(COUNTIF(CO!A:A,A9)>0,COUNTIF('NO2'!A:A,A9)>0,COUNTIF('PM10'!A:A,A9)>0,COUNTIF('PM2.5'!A:A,A9)>0,COUNTIF('SO2'!A:A,A9)>0,COUNTIF(Kendaraan!A:A,A9)>0) -> TRUE
A10: 45383 | B10: 37.72 | C10: 40.22 | D10: 39.67 | E10: 39.14 | F10: 40.02 | G10: 0.678 | H10: 21 | I10: =AND(COUNTIF(CO!A:A,A10)>0,COUNTIF('NO2'!A:A,A10)>0,COUNTIF('PM10'!A:A,A10)>0,COUNTIF('PM2.5'!A:A,A10)>0,COUNTIF('SO2'!A:A,A10)>0,COUNTIF(Kendaraan!A:A,A10)>0) -> TRUE
A11: 45384 | B11: 38.61 | C11: 42.44 | D11: 39.47 | E11: 38.97 | F11: 40.21 | G11: 1096 | H11: 24 | I11: =AND(COUNTIF(CO!A:A,A11)>0,COUNTIF('NO2'!A:A,A11)>0,COUNTIF('PM10'!A:A,A11)>0,COUNTIF('PM2.5'!A:A,A11)>0,COUNTIF('SO2'!A:A,A11)>0,COUNTIF(Kendaraan!A:A,A11)>0) -> TRUE
A12: 45385 | B12: 41.92 | C12: 46.54 | D12: 42.61 | E12: 42.01 | F12: 46.25 | G12: 1956 | H12: 24 | I12: =AND(COUNTIF(CO!A:A,A12)>0,COUNTIF('NO2'!A:A,A12)>0,COUNTIF('PM10'!A:A,A12)>0,COUNTIF('PM2.5'!A:A,A12)>0,COUNTIF('SO2'!A:A,A12)>0,COUNTIF(Kendaraan!A:A,A12)>0) -> TRUE
A13: 45386 | B13: 43.83 | C13: 47.35 | D13: 46.31 | E13: 44.2 | F13: 47.03 | G13: 1328 | H13: 24 | I13: =AND(COUNTIF(CO!A:A,A13)>0,COUNTIF('NO2'!A:A,A13)>0,COUNTIF('PM10'!A:A,A13)>0,COUNTIF('PM2.5'!A:A,A13)>0,COUNTIF('SO2'!A:A,A13)>0,COUNTIF(Kendaraan!A:A,A13)>0) -> TRUE
A14: 45387 | B14: 39 | C14: 43.88 | D14: 43.19 | E14: 41.25 | F14: 43.31 | G14: 1436 | H14: 23 | I14: =AND(COUNTIF(CO!A:A,A14)>0,COUNTIF('NO2'!A:A,A14)>0,COUNTIF('PM10'!A:A,A14)>0,COUNTIF('PM2.5'!A:A,A14)>0,COUNTIF('SO2'!A:A,A14)>0,COUNTIF(Kendaraan!A:A,A14)>0) -> TRUE
A15: 45388 | B15: 38.47 | C15: 40.6 | D15: 39.46 | E15: 38.92 | F15: 40.04 | G15: 0.638 | H15: 24 | I15: =AND(COUNTIF(CO!A:A,A15)>0,COUNTIF('NO2'!A:A,A15)>0,COUNTIF('PM10'!A:A,A15)>0,COUNTIF('PM2.5'!A:A,A15)>0,COUNTIF('SO2'!A:A,A15)>0,COUNTIF(Kendaraan!A:A,A15)>0) -> TRUE
A16: 45389 | B16: 40.08 | C16: 42.56 | D16: 41.92 | E16: 41.28 | F16: 42.15 | G16: 0.699 | H16: 24 | I16: =AND(COUNTIF(CO!A:A,A16)>0,COUNTIF('NO2'!A:A,A16)>0,COUNTIF('PM10'!A:A,A16)>0,COUNTIF('PM2.5'!A:A,A16)>0,COUNTIF('SO2'!A:A,A16)>0,COUNTIF(Kendaraan!A:A,A16)>0) -> TRUE
A17: 45390 | B17: 38.02 | C17: 41.35 | D17: 39.29 | E17: 38.43 | F17: 40.54 | G17: 1111 | H17: 24 | I17: =AND(COUNTIF(CO!A:A,A17)>0,COUNTIF('NO2'!A:A,A17)>0,COUNTIF('PM10'!A:A,A17)>0,COUNTIF('PM2.5'!A:A,A17)>0,COUNTIF('SO2'!A:A,A17)>0,COUNTIF(Kendaraan!A:A,A17)>0) -> TRUE
A18: 45391 | B18: 36.72 | C18: 39.33 | D18: 38.47 | E18: 37.83 | F18: 38.89 | G18: 0.715 | H18: 24 | I18: =AND(COUNTIF(CO!A:A,A18)>0,COUNTIF('NO2'!A:A,A18)>0,COUNTIF('PM10'!A:A,A18)>0,COUNTIF('PM2.5'!A:A,A18)>0,COUNTIF('SO2'!A:A,A18)>0,COUNTIF(Kendaraan!A:A,A18)>0) -> TRUE
A19: 45392 | B19: 34.42 | C19: 36.72 | D19: 35.58 | E19: 34.84 | F19: 35.86 | G19: 0.594 | H19: 24 | I19: =AND(COUNTIF(CO!A:A,A19)>0,COUNTIF('NO2'!A:A,A19)>0,COUNTIF('PM10'!A:A,A19)>0,COUNTIF('PM2.5'!A:A,A19)>0,COUNTIF('SO2'!A:A,A19)>0,COUNTIF(Kendaraan!A:A,A19)>0) -> TRUE
A20: 45393 | B20: 33.1 | C20: 35.29 | D20: 34.45 | E20: 33.72 | F20: 35.11 | G20: 0.738 | H20: 24 | I20: =AND(COUNTIF(CO!A:A,A20)>0,COUNTIF('NO2'!A:A,A20)>0,COUNTIF('PM10'!A:A,A20)>0,COUNTIF('PM2.5'!A:A,A20)>0,COUNTIF('SO2'!A:A,A20)>0,COUNTIF(Kendaraan!A:A,A20)>0) -> TRUE
A21: 45394 | B21: 33.22 | C21: 39.29 | D21: 34.13 | E21: 33.46 | F21: 37.15 | G21: 1892 | H21: 24 | I21: =AND(COUNTIF(CO!A:A,A21)>0,COUNTIF('NO2'!A:A,A21)>0,COUNTIF('PM10'!A:A,A21)>0,COUNTIF('PM2.5'!A:A,A21)>0,COUNTIF('SO2'!A:A,A21)>0,COUNTIF(Kendaraan!A:A,A21)>0) -> TRUE
A22: 45395 | B22: 38.85 | C22: 41.27 | D22: 39.24 | E22: 39.09 | F22: 39.59 | G22: 0.65 | H22: 24 | I22: =AND(COUNTIF(CO!A:A,A22)>0,COUNTIF('NO2'!A:A,A22)>0,COUNTIF('PM10'!A:A,A22)>0,COUNTIF('PM2.5'!A:A,A22)>0,COUNTIF('SO2'!A:A,A22)>0,COUNTIF(Kendaraan!A:A,A22)>0) -> TRUE
A23: 45396 | B23: 39.27 | C23: 39.97 | D23: 39.63 | E23: 39.49 | F23: 39.76 | G23: 0.188 | H23: 24 | I23: =AND(COUNTIF(CO!A:A,A23)>0,COUNTIF('NO2'!A:A,A23)>0,COUNTIF('PM10'!A:A,A23)>0,COUNTIF('PM2.5'!A:A,A23)>0,COUNTIF('SO2'!A:A,A23)>0,COUNTIF(Kendaraan!A:A,A23)>0) -> TRUE
A24: 45397 | B24: 39.52 | C24: 44.56 | D24: 40.98 | E24: 40.32 | F24: 42.91 | G24: 1512 | H24: 24 | I24: =AND(COUNTIF(CO!A:A,A24)>0,COUNTIF('NO2'!A:A,A24)>0,COUNTIF('PM10'!A:A,A24)>0,COUNTIF('PM2.5'!A:A,A24)>0,COUNTIF('SO2'!A:A,A24)>0,COUNTIF(Kendaraan!A:A,A24)>0) -> TRUE
A25: 45398 | B25: 39.38 | C25: 44.69 | D25: 43.81 | E25: 41.26 | F25: 44.26 | G25: 1671 | H25: 24 | I25: =AND(COUNTIF(CO!A:A,A25)>0,COUNTIF('NO2'!A:A,A25)>0,COUNTIF('PM10'!A:A,A25)>0,COUNTIF('PM2.5'!A:A,A25)>0,COUNTIF('SO2'!A:A,A25)>0,COUNTIF(Kendaraan!A:A,A25)>0) -> TRUE
A26: 45399 | B26: 37.31 | C26: 39.35 | D26: 38.75 | E26: 37.54 | F26: 39.15 | G26: 0.814 | H26: 24 | I26: =AND(COUNTIF(CO!A:A,A26)>0,COUNTIF('NO2'!A:A,A26)>0,COUNTIF('PM10'!A:A,A26)>0,COUNTIF('PM2.5'!A:A,A26)>0,COUNTIF('SO2'!A:A,A26)>0,COUNTIF(Kendaraan!A:A,A26)>0) -> TRUE
A27: 45400 | B27: 36.25 | C27: 38.08 | D27: 37.17 | E27: 37.02 | F27: 37.59 | G27: 0.417 | H27: 24 | I27: =AND(COUNTIF(CO!A:A,A27)>0,COUNTIF('NO2'!A:A,A27)>0,COUNTIF('PM10'!A:A,A27)>0,COUNTIF('PM2.5'!A:A,A27)>0,COUNTIF('SO2'!A:A,A27)>0,COUNTIF(Kendaraan!A:A,A27)>0) -> TRUE
A28: 45401 | B28: 33.72 | C28: 36.22 | D28: 35.1 | E28: 34.03 | F28: 35.81 | G28: 0.878 | H28: 24 | I28: =AND(COUNTIF(CO!A:A,A28)>0,COUNTIF('NO2'!A:A,A28)>0,COUNTIF('PM10'!A:A,A28)>0,COUNTIF('PM2.5'!A:A,A28)>0,COUNTIF('SO2'!A:A,A28)>0,COUNTIF(Kendaraan!A:A,A28)>0) -> TRUE
A29: 45402 | B29: 33.81 | C29: 38.21 | D29: 33.99 | E29: 33.9 | F29: 36.09 | G29: 1361 | H29: 24 | I29: =AND(COUNTIF(CO!A:A,A29)>0,COUNTIF('NO2'!A:A,A29)>0,COUNTIF('PM10'!A:A,A29)>0,COUNTIF('PM2.5'!A:A,A29)>0,COUNTIF('SO2'!A:A,A29)>0,COUNTIF(Kendaraan!A:A,A29)>0) -> TRUE
A30: 45403 | B30: 34.69 | C30: 39.71 | D30: 38.65 | E30: 37.06 | F30: 39.29 | G30: 1475 | H30: 24 | I30: =AND(COUNTIF(CO!A:A,A30)>0,COUNTIF('NO2'!A:A,A30)>0,COUNTIF('PM10'!A:A,A30)>0,COUNTIF('PM2.5'!A:A,A30)>0,COUNTIF('SO2'!A:A,A30)>0,COUNTIF(Kendaraan!A:A,A30)>0) -> TRUE
A31: 45404 | B31: 33.56 | C31: 39.04 | D31: 34.39 | E31: 33.88 | F31: 36.09 | G31: 1536 | H31: 24 | I31: =AND(COUNTIF(CO!A:A,A31)>0,COUNTIF('NO2'!A:A,A31)>0,COUNTIF('PM10'!A:A,A31)>0,COUNTIF('PM2.5'!A:A,A31)>0,COUNTIF('SO2'!A:A,A31)>0,COUNTIF(Kendaraan!A:A,A31)>0) -> TRUE
A32: 45405 | B32: 34.88 | C32: 39.22 | D32: 38.57 | E32: 37.13 | F32: 38.92 | G32: 1.21 | H32: 24 | I32: =AND(COUNTIF(CO!A:A,A32)>0,COUNTIF('NO2'!A:A,A32)>0,COUNTIF('PM10'!A:A,A32)>0,COUNTIF('PM2.5'!A:A,A32)>0,COUNTIF('SO2'!A:A,A32)>0,COUNTIF(Kendaraan!A:A,A32)>0) -> TRUE
A33: 45406 | B33: 34.6 | C33: 41.17 | D33: 35.24 | E33: 34.92 | F33: 38.35 | G33: 2127 | H33: 24 | I33: =AND(COUNTIF(CO!A:A,A33)>0,COUNTIF('NO2'!A:A,A33)>0,COUNTIF('PM10'!A:A,A33)>0,COUNTIF('PM2.5'!A:A,A33)>0,COUNTIF('SO2'!A:A,A33)>0,COUNTIF(Kendaraan!A:A,A33)>0) -> TRUE
A34: 45407 | B34: 39.22 | C34: 42.06 | D34: 41.18 | E34: 39.89 | F34: 41.72 | G34: 0.927 | H34: 24 | I34: =AND(COUNTIF(CO!A:A,A34)>0,COUNTIF('NO2'!A:A,A34)>0,COUNTIF('PM10'!A:A,A34)>0,COUNTIF('PM2.5'!A:A,A34)>0,COUNTIF('SO2'!A:A,A34)>0,COUNTIF(Kendaraan!A:A,A34)>0) -> TRUE
A35: 45408 | B35: 39.71 | C35: 43.42 | D35: 40.69 | E35: 40.39 | F35: 43.05 | G35: 1272 | H35: 24 | I35: =AND(COUNTIF(CO!A:A,A35)>0,COUNTIF('NO2'!A:A,A35)>0,COUNTIF('PM10'!A:A,A35)>0,COUNTIF('PM2.5'!A:A,A35)>0,COUNTIF('SO2'!A:A,A35)>0,COUNTIF(Kendaraan!A:A,A35)>0) -> TRUE
A36: 45409 | B36: 42.29 | C36: 43.96 | D36: 42.77 | E36: 42.47 | F36: 43.18 | G36: 0.491 | H36: 24 | I36: =AND(COUNTIF(CO!A:A,A36)>0,COUNTIF('NO2'!A:A,A36)>0,COUNTIF('PM10'!A:A,A36)>0,COUNTIF('PM2.5'!A:A,A36)>0,COUNTIF('SO2'!A:A,A36)>0,COUNTIF(Kendaraan!A:A,A36)>0) -> TRUE
A37: 45410 | B37: 44 | C37: 45.38 | D37: 44.25 | E37: 44.18 | F37: 44.94 | G37: 0.443 | H37: 24 | I37: =AND(COUNTIF(CO!A:A,A37)>0,COUNTIF('NO2'!A:A,A37)>0,COUNTIF('PM10'!A:A,A37)>0,COUNTIF('PM2.5'!A:A,A37)>0,COUNTIF('SO2'!A:A,A37)>0,COUNTIF(Kendaraan!A:A,A37)>0) -> TRUE
A38: 45411 | B38: 43.75 | C38: 44.79 | D38: 44.41 | E38: 44.04 | F38: 44.53 | G38: 0.3 | H38: 24 | I38: =AND(COUNTIF(CO!A:A,A38)>0,COUNTIF('NO2'!A:A,A38)>0,COUNTIF('PM10'!A:A,A38)>0,COUNTIF('PM2.5'!A:A,A38)>0,COUNTIF('SO2'!A:A,A38)>0,COUNTIF(Kendaraan!A:A,A38)>0) -> TRUE
A39: 45412 | B39: 39.31 | C39: 43.5 | D39: 42.43 | E39: 41.11 | F39: 42.82 | G39: 1267 | H39: 24 | I39: =AND(COUNTIF(CO!A:A,A39)>0,COUNTIF('NO2'!A:A,A39)>0,COUNTIF('PM10'!A:A,A39)>0,COUNTIF('PM2.5'!A:A,A39)>0,COUNTIF('SO2'!A:A,A39)>0,COUNTIF(Kendaraan!A:A,A39)>0) -> TRUE
A40: 45413 | B40: 35.25 | C40: 40.29 | D40: 39.44 | E40: 37.08 | F40: 40.02 | G40: 1648 | H40: 24 | I40: =AND(COUNTIF(CO!A:A,A40)>0,COUNTIF('NO2'!A:A,A40)>0,COUNTIF('PM10'!A:A,A40)>0,COUNTIF('PM2.5'!A:A,A40)>0,COUNTIF('SO2'!A:A,A40)>0,COUNTIF(Kendaraan!A:A,A40)>0) -> TRUE
...

Sheet PM10
A1: date | B1: min | C1: max | D1: median | E1: q1 | F1: q3 | G1: stdev | H1: count | I1: cek
A2: 45337 | B2: 12 | C2: 18.73 | D2: 13.76 | E2: 12.45 | F2: 15.61 | G2: 2029 | H2: 24 | I2: =AND(COUNTIF(CO!A:A,A2)>0,COUNTIF('NO2'!A:A,A2)>0,COUNTIF('O3'!A:A,A2)>0,COUNTIF('PM2.5'!A:A,A2)>0,COUNTIF('SO2'!A:A,A2)>0,COUNTIF(Kendaraan!A:A,A2)>0) -> TRUE
A3: 45338 | B3: 5 | C3: 20.27 | D3: 15.49 | E3: 10.88 | F3: 18.16 | G3: 4522 | H3: 24 | I3: =AND(COUNTIF(CO!A:A,A3)>0,COUNTIF('NO2'!A:A,A3)>0,COUNTIF('O3'!A:A,A3)>0,COUNTIF('PM2.5'!A:A,A3)>0,COUNTIF('SO2'!A:A,A3)>0,COUNTIF(Kendaraan!A:A,A3)>0) -> TRUE
A4: 45342 | B4: 14.42 | C4: 17.73 | D4: 16.67 | E4: 15.27 | F4: 17.26 | G4: 1155 | H4: 24 | I4: =AND(COUNTIF(CO!A:A,A4)>0,COUNTIF('NO2'!A:A,A4)>0,COUNTIF('O3'!A:A,A4)>0,COUNTIF('PM2.5'!A:A,A4)>0,COUNTIF('SO2'!A:A,A4)>0,COUNTIF(Kendaraan!A:A,A4)>0) -> TRUE
A5: 45343 | B5: 4.38 | C5: 14.46 | D5: 11.09 | E5: 7.59 | F5: 14.15 | G5: 3383 | H5: 24 | I5: =AND(COUNTIF(CO!A:A,A5)>0,COUNTIF('NO2'!A:A,A5)>0,COUNTIF('O3'!A:A,A5)>0,COUNTIF('PM2.5'!A:A,A5)>0,COUNTIF('SO2'!A:A,A5)>0,COUNTIF(Kendaraan!A:A,A5)>0) -> TRUE
A6: 45344 | B6: 0.28 | C6: 3.79 | D6: 2.04 | E6: 0.88 | F6: 3.21 | G6: 1166 | H6: 7 | I6: =AND(COUNTIF(CO!A:A,A6)>0,COUNTIF('NO2'!A:A,A6)>0,COUNTIF('O3'!A:A,A6)>0,COUNTIF('PM2.5'!A:A,A6)>0,COUNTIF('SO2'!A:A,A6)>0,COUNTIF(Kendaraan!A:A,A6)>0) -> TRUE
A7: 45372 | B7: 17.5 | C7: 20.02 | D7: 19.5 | E7: 18.43 | F7: 19.79 | G7: 0.803 | H7: 9 | I7: =AND(COUNTIF(CO!A:A,A7)>0,COUNTIF('NO2'!A:A,A7)>0,COUNTIF('O3'!A:A,A7)>0,COUNTIF('PM2.5'!A:A,A7)>0,COUNTIF('SO2'!A:A,A7)>0,COUNTIF(Kendaraan!A:A,A7)>0) -> TRUE
A8: 45373 | B8: 29.6 | C8: 29.96 | D8: 29.73 | E8: 29.61 | F8: 29.9 | G8: 0.15 | H8: 4 | I8: =AND(COUNTIF(CO!A:A,A8)>0,COUNTIF('NO2'!A:A,A8)>0,COUNTIF('O3'!A:A,A8)>0,COUNTIF('PM2.5'!A:A,A8)>0,COUNTIF('SO2'!A:A,A8)>0,COUNTIF(Kendaraan!A:A,A8)>0) -> TRUE
A9: 45377 | B9: 19.3 | C9: 19.3 | D9: 19.3 | E9: 19.3 | F9: 19.3 | G9: 0 | H9: 1 | I9: =AND(COUNTIF(CO!A:A,A9)>0,COUNTIF('NO2'!A:A,A9)>0,COUNTIF('O3'!A:A,A9)>0,COUNTIF('PM2.5'!A:A,A9)>0,COUNTIF('SO2'!A:A,A9)>0,COUNTIF(Kendaraan!A:A,A9)>0) -> TRUE
A10: 45383 | B10: 10.77 | C10: 12.83 | D10: 11.58 | E10: 11.33 | F10: 12.57 | G10: 0.672 | H10: 21 | I10: =AND(COUNTIF(CO!A:A,A10)>0,COUNTIF('NO2'!A:A,A10)>0,COUNTIF('O3'!A:A,A10)>0,COUNTIF('PM2.5'!A:A,A10)>0,COUNTIF('SO2'!A:A,A10)>0,COUNTIF(Kendaraan!A:A,A10)>0) -> TRUE
A11: 45384 | B11: 12.04 | C11: 13.21 | D11: 12.55 | E11: 12.39 | F11: 13.02 | G11: 0.368 | H11: 24 | I11: =AND(COUNTIF(CO!A:A,A11)>0,COUNTIF('NO2'!A:A,A11)>0,COUNTIF('O3'!A:A,A11)>0,COUNTIF('PM2.5'!A:A,A11)>0,COUNTIF('SO2'!A:A,A11)>0,COUNTIF(Kendaraan!A:A,A11)>0) -> TRUE
A12: 45385 | B12: 13.17 | C12: 17.23 | D12: 16.45 | E12: 14.34 | F12: 17.02 | G12: 1306 | H12: 24 | I12: =AND(COUNTIF(CO!A:A,A12)>0,COUNTIF('NO2'!A:A,A12)>0,COUNTIF('O3'!A:A,A12)>0,COUNTIF('PM2.5'!A:A,A12)>0,COUNTIF('SO2'!A:A,A12)>0,COUNTIF(Kendaraan!A:A,A12)>0) -> TRUE
A13: 45386 | B13: 13.25 | C13: 16.3 | D13: 14 | E13: 13.52 | F13: 15.66 | G13: 1041 | H13: 24 | I13: =AND(COUNTIF(CO!A:A,A13)>0,COUNTIF('NO2'!A:A,A13)>0,COUNTIF('O3'!A:A,A13)>0,COUNTIF('PM2.5'!A:A,A13)>0,COUNTIF('SO2'!A:A,A13)>0,COUNTIF(Kendaraan!A:A,A13)>0) -> TRUE
A14: 45387 | B14: 12.17 | C14: 15.54 | D14: 13.08 | E14: 12.54 | F14: 14.54 | G14: 1129 | H14: 23 | I14: =AND(COUNTIF(CO!A:A,A14)>0,COUNTIF('NO2'!A:A,A14)>0,COUNTIF('O3'!A:A,A14)>0,COUNTIF('PM2.5'!A:A,A14)>0,COUNTIF('SO2'!A:A,A14)>0,COUNTIF(Kendaraan!A:A,A14)>0) -> TRUE
A15: 45388 | B15: 13.88 | C15: 16.75 | D15: 15.4 | E15: 15.04 | F15: 16.3 | G15: 0.824 | H15: 24 | I15: =AND(COUNTIF(CO!A:A,A15)>0,COUNTIF('NO2'!A:A,A15)>0,COUNTIF('O3'!A:A,A15)>0,COUNTIF('PM2.5'!A:A,A15)>0,COUNTIF('SO2'!A:A,A15)>0,COUNTIF(Kendaraan!A:A,A15)>0) -> TRUE
A16: 45389 | B16: 17.57 | C16: 23.21 | D16: 20.3 | E16: 19.01 | F16: 21.49 | G16: 1519 | H16: 24 | I16: =AND(COUNTIF(CO!A:A,A16)>0,COUNTIF('NO2'!A:A,A16)>0,COUNTIF('O3'!A:A,A16)>0,COUNTIF('PM2.5'!A:A,A16)>0,COUNTIF('SO2'!A:A,A16)>0,COUNTIF(Kendaraan!A:A,A16)>0) -> TRUE
A17: 45390 | B17: 14.98 | C17: 21.21 | D17: 19.64 | E17: 17.84 | F17: 19.92 | G17: 1784 | H17: 24 | I17: =AND(COUNTIF(CO!A:A,A17)>0,COUNTIF('NO2'!A:A,A17)>0,COUNTIF('O3'!A:A,A17)>0,COUNTIF('PM2.5'!A:A,A17)>0,COUNTIF('SO2'!A:A,A17)>0,COUNTIF(Kendaraan!A:A,A17)>0) -> TRUE
A18: 45391 | B18: 16.19 | C18: 17.82 | D18: 17.44 | E18: 16.95 | F18: 17.69 | G18: 0.472 | H18: 24 | I18: =AND(COUNTIF(CO!A:A,A18)>0,COUNTIF('NO2'!A:A,A18)>0,COUNTIF('O3'!A:A,A18)>0,COUNTIF('PM2.5'!A:A,A18)>0,COUNTIF('SO2'!A:A,A18)>0,COUNTIF(Kendaraan!A:A,A18)>0) -> TRUE
A19: 45392 | B19: 9.78 | C19: 16.73 | D19: 13.62 | E19: 10.08 | F19: 14.94 | G19: 2441 | H19: 24 | I19: =AND(COUNTIF(CO!A:A,A19)>0,COUNTIF('NO2'!A:A,A19)>0,COUNTIF('O3'!A:A,A19)>0,COUNTIF('PM2.5'!A:A,A19)>0,COUNTIF('SO2'!A:A,A19)>0,COUNTIF(Kendaraan!A:A,A19)>0) -> TRUE
A20: 45393 | B20: 9.69 | C20: 10.6 | D20: 10.05 | E20: 9.94 | F20: 10.28 | G20: 0.233 | H20: 24 | I20: =AND(COUNTIF(CO!A:A,A20)>0,COUNTIF('NO2'!A:A,A20)>0,COUNTIF('O3'!A:A,A20)>0,COUNTIF('PM2.5'!A:A,A20)>0,COUNTIF('SO2'!A:A,A20)>0,COUNTIF(Kendaraan!A:A,A20)>0) -> TRUE
A21: 45394 | B21: 10.67 | C21: 16.73 | D21: 11.39 | E21: 10.8 | F21: 15.12 | G21: 2251 | H21: 24 | I21: =AND(COUNTIF(CO!A:A,A21)>0,COUNTIF('NO2'!A:A,A21)>0,COUNTIF('O3'!A:A,A21)>0,COUNTIF('PM2.5'!A:A,A21)>0,COUNTIF('SO2'!A:A,A21)>0,COUNTIF(Kendaraan!A:A,A21)>0) -> TRUE
A22: 45395 | B22: 15.4 | C22: 18.1 | D22: 17.22 | E22: 16.23 | F22: 17.48 | G22: 0.767 | H22: 24 | I22: =AND(COUNTIF(CO!A:A,A22)>0,COUNTIF('NO2'!A:A,A22)>0,COUNTIF('O3'!A:A,A22)>0,COUNTIF('PM2.5'!A:A,A22)>0,COUNTIF('SO2'!A:A,A22)>0,COUNTIF(Kendaraan!A:A,A22)>0) -> TRUE
A23: 45396 | B23: 15.48 | C23: 17.67 | D23: 17.39 | E23: 17.13 | F23: 17.47 | G23: 0.508 | H23: 24 | I23: =AND(COUNTIF(CO!A:A,A23)>0,COUNTIF('NO2'!A:A,A23)>0,COUNTIF('O3'!A:A,A23)>0,COUNTIF('PM2.5'!A:A,A23)>0,COUNTIF('SO2'!A:A,A23)>0,COUNTIF(Kendaraan!A:A,A23)>0) -> TRUE
A24: 45397 | B24: 17 | C24: 20.79 | D24: 18.45 | E24: 17.2 | F24: 19.98 | G24: 1408 | H24: 24 | I24: =AND(COUNTIF(CO!A:A,A24)>0,COUNTIF('NO2'!A:A,A24)>0,COUNTIF('O3'!A:A,A24)>0,COUNTIF('PM2.5'!A:A,A24)>0,COUNTIF('SO2'!A:A,A24)>0,COUNTIF(Kendaraan!A:A,A24)>0) -> TRUE
A25: 45398 | B25: 17.14 | C25: 20.9 | D25: 19.44 | E25: 18.57 | F25: 19.95 | G25: 0.966 | H25: 24 | I25: =AND(COUNTIF(CO!A:A,A25)>0,COUNTIF('NO2'!A:A,A25)>0,COUNTIF('O3'!A:A,A25)>0,COUNTIF('PM2.5'!A:A,A25)>0,COUNTIF('SO2'!A:A,A25)>0,COUNTIF(Kendaraan!A:A,A25)>0) -> TRUE
A26: 45399 | B26: 11.71 | C26: 16.8 | D26: 13.72 | E26: 12.59 | F26: 15.17 | G26: 1518 | H26: 24 | I26: =AND(COUNTIF(CO!A:A,A26)>0,COUNTIF('NO2'!A:A,A26)>0,COUNTIF('O3'!A:A,A26)>0,COUNTIF('PM2.5'!A:A,A26)>0,COUNTIF('SO2'!A:A,A26)>0,COUNTIF(Kendaraan!A:A,A26)>0) -> TRUE
A27: 45400 | B27: 14.1 | C27: 18.02 | D27: 16.42 | E27: 16.05 | F27: 17.1 | G27: 1071 | H27: 24 | I27: =AND(COUNTIF(CO!A:A,A27)>0,COUNTIF('NO2'!A:A,A27)>0,COUNTIF('O3'!A:A,A27)>0,COUNTIF('PM2.5'!A:A,A27)>0,COUNTIF('SO2'!A:A,A27)>0,COUNTIF(Kendaraan!A:A,A27)>0) -> TRUE
A28: 45401 | B28: 9.96 | C28: 14.38 | D28: 11.97 | E28: 10.42 | F28: 12.99 | G28: 1489 | H28: 24 | I28: =AND(COUNTIF(CO!A:A,A28)>0,COUNTIF('NO2'!A:A,A28)>0,COUNTIF('O3'!A:A,A28)>0,COUNTIF('PM2.5'!A:A,A28)>0,COUNTIF('SO2'!A:A,A28)>0,COUNTIF(Kendaraan!A:A,A28)>0) -> TRUE
A29: 45402 | B29: 10.75 | C29: 19.85 | D29: 16 | E29: 12.71 | F29: 18.1 | G29: 2851 | H29: 24 | I29: =AND(COUNTIF(CO!A:A,A29)>0,COUNTIF('NO2'!A:A,A29)>0,COUNTIF('O3'!A:A,A29)>0,COUNTIF('PM2.5'!A:A,A29)>0,COUNTIF('SO2'!A:A,A29)>0,COUNTIF(Kendaraan!A:A,A29)>0) -> TRUE
A30: 45403 | B30: 17.94 | C30: 22.6 | D30: 19.93 | E30: 19.1 | F30: 22.11 | G30: 1529 | H30: 24 | I30: =AND(COUNTIF(CO!A:A,A30)>0,COUNTIF('NO2'!A:A,A30)>0,COUNTIF('O3'!A:A,A30)>0,COUNTIF('PM2.5'!A:A,A30)>0,COUNTIF('SO2'!A:A,A30)>0,COUNTIF(Kendaraan!A:A,A30)>0) -> TRUE
A31: 45404 | B31: 12.15 | C31: 17.64 | D31: 13.23 | E31: 12.91 | F31: 13.57 | G31: 1484 | H31: 24 | I31: =AND(COUNTIF(CO!A:A,A31)>0,COUNTIF('NO2'!A:A,A31)>0,COUNTIF('O3'!A:A,A31)>0,COUNTIF('PM2.5'!A:A,A31)>0,COUNTIF('SO2'!A:A,A31)>0,COUNTIF(Kendaraan!A:A,A31)>0) -> TRUE
A32: 45405 | B32: 13.06 | C32: 21.21 | D32: 14.79 | E32: 14.17 | F32: 16.04 | G32: 2032 | H32: 24 | I32: =AND(COUNTIF(CO!A:A,A32)>0,COUNTIF('NO2'!A:A,A32)>0,COUNTIF('O3'!A:A,A32)>0,COUNTIF('PM2.5'!A:A,A32)>0,COUNTIF('SO2'!A:A,A32)>0,COUNTIF(Kendaraan!A:A,A32)>0) -> TRUE
A33: 45406 | B33: 22.52 | C33: 31.98 | D33: 29.46 | E33: 28.14 | F33: 30.83 | G33: 2325 | H33: 24 | I33: =AND(COUNTIF(CO!A:A,A33)>0,COUNTIF('NO2'!A:A,A33)>0,COUNTIF('O3'!A:A,A33)>0,COUNTIF('PM2.5'!A:A,A33)>0,COUNTIF('SO2'!A:A,A33)>0,COUNTIF(Kendaraan!A:A,A33)>0) -> TRUE
A34: 45407 | B34: 24.96 | C34: 28.58 | D34: 27.47 | E34: 27.16 | F34: 27.93 | G34: 0.762 | H34: 24 | I34: =AND(COUNTIF(CO!A:A,A34)>0,COUNTIF('NO2'!A:A,A34)>0,COUNTIF('O3'!A:A,A34)>0,COUNTIF('PM2.5'!A:A,A34)>0,COUNTIF('SO2'!A:A,A34)>0,COUNTIF(Kendaraan!A:A,A34)>0) -> TRUE
A35: 45408 | B35: 20.02 | C35: 24.31 | D35: 21.1 | E35: 20.43 | F35: 22.07 | G35: 1219 | H35: 24 | I35: =AND(COUNTIF(CO!A:A,A35)>0,COUNTIF('NO2'!A:A,A35)>0,COUNTIF('O3'!A:A,A35)>0,COUNTIF('PM2.5'!A:A,A35)>0,COUNTIF('SO2'!A:A,A35)>0,COUNTIF(Kendaraan!A:A,A35)>0) -> TRUE
A36: 45409 | B36: 15.9 | C36: 25.42 | D36: 17.67 | E36: 17.36 | F36: 20.29 | G36: 2401 | H36: 24 | I36: =AND(COUNTIF(CO!A:A,A36)>0,COUNTIF('NO2'!A:A,A36)>0,COUNTIF('O3'!A:A,A36)>0,COUNTIF('PM2.5'!A:A,A36)>0,COUNTIF('SO2'!A:A,A36)>0,COUNTIF(Kendaraan!A:A,A36)>0) -> TRUE
A37: 45410 | B37: 26.46 | C37: 32.08 | D37: 29.48 | E37: 28.04 | F37: 30.73 | G37: 1.61 | H37: 24 | I37: =AND(COUNTIF(CO!A:A,A37)>0,COUNTIF('NO2'!A:A,A37)>0,COUNTIF('O3'!A:A,A37)>0,COUNTIF('PM2.5'!A:A,A37)>0,COUNTIF('SO2'!A:A,A37)>0,COUNTIF(Kendaraan!A:A,A37)>0) -> TRUE
A38: 45411 | B38: 24.31 | C38: 28.62 | D38: 26.41 | E38: 25.89 | F38: 27.99 | G38: 1308 | H38: 24 | I38: =AND(COUNTIF(CO!A:A,A38)>0,COUNTIF('NO2'!A:A,A38)>0,COUNTIF('O3'!A:A,A38)>0,COUNTIF('PM2.5'!A:A,A38)>0,COUNTIF('SO2'!A:A,A38)>0,COUNTIF(Kendaraan!A:A,A38)>0) -> TRUE
A39: 45412 | B39: 28.44 | C39: 32.9 | D39: 31.45 | E39: 29.35 | F39: 32.45 | G39: 1605 | H39: 24 | I39: =AND(COUNTIF(CO!A:A,A39)>0,COUNTIF('NO2'!A:A,A39)>0,COUNTIF('O3'!A:A,A39)>0,COUNTIF('PM2.5'!A:A,A39)>0,COUNTIF('SO2'!A:A,A39)>0,COUNTIF(Kendaraan!A:A,A39)>0) -> TRUE
A40: 45413 | B40: 26.81 | C40: 34 | D40: 30.47 | E40: 28.02 | F40: 33.25 | G40: 2505 | H40: 24 | I40: =AND(COUNTIF(CO!A:A,A40)>0,COUNTIF('NO2'!A:A,A40)>0,COUNTIF('O3'!A:A,A40)>0,COUNTIF('PM2.5'!A:A,A40)>0,COUNTIF('SO2'!A:A,A40)>0,COUNTIF(Kendaraan!A:A,A40)>0) -> TRUE
...

Sheet PM2.5
A1: date | B1: min | C1: max | D1: median | E1: q1 | F1: q3 | G1: stdev | H1: count | I1: cek
A2: 45337 | B2: 12.85 | C2: 18.21 | D2: 14.02 | E2: 13.11 | F2: 15.43 | G2: 1562 | H2: 24 | I2: =AND(COUNTIF(CO!A:A,A2)>0,COUNTIF('NO2'!A:A,A2)>0,COUNTIF('O3'!A:A,A2)>0,COUNTIF('PM10'!A:A,A2)>0,COUNTIF('SO2'!A:A,A2)>0,COUNTIF(Kendaraan!A:A,A2)>0) -> TRUE
A3: 45338 | B3: 5.04 | C3: 19.82 | D3: 15.18 | E3: 10.8 | F3: 17.84 | G3: 4347 | H3: 24 | I3: =AND(COUNTIF(CO!A:A,A3)>0,COUNTIF('NO2'!A:A,A3)>0,COUNTIF('O3'!A:A,A3)>0,COUNTIF('PM10'!A:A,A3)>0,COUNTIF('SO2'!A:A,A3)>0,COUNTIF(Kendaraan!A:A,A3)>0) -> TRUE
A4: 45342 | B4: 14.81 | C4: 17.89 | D4: 17.17 | E4: 16.37 | F4: 17.61 | G4: 0.83 | H4: 24 | I4: =AND(COUNTIF(CO!A:A,A4)>0,COUNTIF('NO2'!A:A,A4)>0,COUNTIF('O3'!A:A,A4)>0,COUNTIF('PM10'!A:A,A4)>0,COUNTIF('SO2'!A:A,A4)>0,COUNTIF(Kendaraan!A:A,A4)>0) -> TRUE
A5: 45343 | B5: 5.94 | C5: 18.94 | D5: 15.05 | E5: 10.3 | F5: 18.13 | G5: 4311 | H5: 24 | I5: =AND(COUNTIF(CO!A:A,A5)>0,COUNTIF('NO2'!A:A,A5)>0,COUNTIF('O3'!A:A,A5)>0,COUNTIF('PM10'!A:A,A5)>0,COUNTIF('SO2'!A:A,A5)>0,COUNTIF(Kendaraan!A:A,A5)>0) -> TRUE
A6: 45344 | B6: 0.4 | C6: 5.15 | D6: 2.77 | E6: 1.19 | F6: 4.34 | G6: 1582 | H6: 7 | I6: =AND(COUNTIF(CO!A:A,A6)>0,COUNTIF('NO2'!A:A,A6)>0,COUNTIF('O3'!A:A,A6)>0,COUNTIF('PM10'!A:A,A6)>0,COUNTIF('SO2'!A:A,A6)>0,COUNTIF(Kendaraan!A:A,A6)>0) -> TRUE
A7: 45372 | B7: 16.94 | C7: 19.39 | D7: 19 | E7: 17.95 | F7: 19.23 | G7: 0.789 | H7: 9 | I7: =AND(COUNTIF(CO!A:A,A7)>0,COUNTIF('NO2'!A:A,A7)>0,COUNTIF('O3'!A:A,A7)>0,COUNTIF('PM10'!A:A,A7)>0,COUNTIF('SO2'!A:A,A7)>0,COUNTIF(Kendaraan!A:A,A7)>0) -> TRUE
A8: 45373 | B8: 29.12 | C8: 29.54 | D8: 29.29 | E8: 29.15 | F8: 29.47 | G8: 0.171 | H8: 4 | I8: =AND(COUNTIF(CO!A:A,A8)>0,COUNTIF('NO2'!A:A,A8)>0,COUNTIF('O3'!A:A,A8)>0,COUNTIF('PM10'!A:A,A8)>0,COUNTIF('SO2'!A:A,A8)>0,COUNTIF(Kendaraan!A:A,A8)>0) -> TRUE
A9: 45377 | B9: 19 | C9: 19 | D9: 19 | E9: 19 | F9: 19 | G9: 0 | H9: 1 | I9: =AND(COUNTIF(CO!A:A,A9)>0,COUNTIF('NO2'!A:A,A9)>0,COUNTIF('O3'!A:A,A9)>0,COUNTIF('PM10'!A:A,A9)>0,COUNTIF('SO2'!A:A,A9)>0,COUNTIF(Kendaraan!A:A,A9)>0) -> TRUE
A10: 45383 | B10: 10.21 | C10: 12.29 | D10: 11.1 | E10: 10.86 | F10: 12.05 | G10: 0.657 | H10: 21 | I10: =AND(COUNTIF(CO!A:A,A10)>0,COUNTIF('NO2'!A:A,A10)>0,COUNTIF('O3'!A:A,A10)>0,COUNTIF('PM10'!A:A,A10)>0,COUNTIF('SO2'!A:A,A10)>0,COUNTIF(Kendaraan!A:A,A10)>0) -> TRUE
A11: 45384 | B11: 11.58 | C11: 12.73 | D11: 12.07 | E11: 11.95 | F11: 12.53 | G11: 0.347 | H11: 24 | I11: =AND(COUNTIF(CO!A:A,A11)>0,COUNTIF('NO2'!A:A,A11)>0,COUNTIF('O3'!A:A,A11)>0,COUNTIF('PM10'!A:A,A11)>0,COUNTIF('SO2'!A:A,A11)>0,COUNTIF(Kendaraan!A:A,A11)>0) -> TRUE
A12: 45385 | B12: 12.81 | C12: 17.23 | D12: 16.38 | E12: 14.08 | F12: 16.97 | G12: 1415 | H12: 24 | I12: =AND(COUNTIF(CO!A:A,A12)>0,COUNTIF('NO2'!A:A,A12)>0,COUNTIF('O3'!A:A,A12)>0,COUNTIF('PM10'!A:A,A12)>0,COUNTIF('SO2'!A:A,A12)>0,COUNTIF(Kendaraan!A:A,A12)>0) -> TRUE
A13: 45386 | B13: 12.77 | C13: 16.3 | D13: 13.67 | E13: 13.15 | F13: 15.63 | G13: 1202 | H13: 24 | I13: =AND(COUNTIF(CO!A:A,A13)>0,COUNTIF('NO2'!A:A,A13)>0,COUNTIF('O3'!A:A,A13)>0,COUNTIF('PM10'!A:A,A13)>0,COUNTIF('SO2'!A:A,A13)>0,COUNTIF(Kendaraan!A:A,A13)>0) -> TRUE
A14: 45387 | B14: 11.65 | C14: 14.98 | D14: 12.56 | E14: 12.02 | F14: 13.94 | G14: 1.1 | H14: 23 | I14: =AND(COUNTIF(CO!A:A,A14)>0,COUNTIF('NO2'!A:A,A14)>0,COUNTIF('O3'!A:A,A14)>0,COUNTIF('PM10'!A:A,A14)>0,COUNTIF('SO2'!A:A,A14)>0,COUNTIF(Kendaraan!A:A,A14)>0) -> TRUE
A15: 45388 | B15: 13.17 | C15: 16.23 | D15: 14.82 | E15: 14.39 | F15: 15.77 | G15: 0.876 | H15: 24 | I15: =AND(COUNTIF(CO!A:A,A15)>0,COUNTIF('NO2'!A:A,A15)>0,COUNTIF('O3'!A:A,A15)>0,COUNTIF('PM10'!A:A,A15)>0,COUNTIF('SO2'!A:A,A15)>0,COUNTIF(Kendaraan!A:A,A15)>0) -> TRUE
A16: 45389 | B16: 17.04 | C16: 22.73 | D16: 19.88 | E16: 18.59 | F16: 21.05 | G16: 1519 | H16: 24 | I16: =AND(COUNTIF(CO!A:A,A16)>0,COUNTIF('NO2'!A:A,A16)>0,COUNTIF('O3'!A:A,A16)>0,COUNTIF('PM10'!A:A,A16)>0,COUNTIF('SO2'!A:A,A16)>0,COUNTIF(Kendaraan!A:A,A16)>0) -> TRUE
A17: 45390 | B17: 14.65 | C17: 20.79 | D17: 19.2 | E17: 17.47 | F17: 19.63 | G17: 1772 | H17: 24 | I17: =AND(COUNTIF(CO!A:A,A17)>0,COUNTIF('NO2'!A:A,A17)>0,COUNTIF('O3'!A:A,A17)>0,COUNTIF('PM10'!A:A,A17)>0,COUNTIF('SO2'!A:A,A17)>0,COUNTIF(Kendaraan!A:A,A17)>0) -> TRUE
A18: 45391 | B18: 15.77 | C18: 17.67 | D18: 17.28 | E18: 16.82 | F18: 17.57 | G18: 0.515 | H18: 24 | I18: =AND(COUNTIF(CO!A:A,A18)>0,COUNTIF('NO2'!A:A,A18)>0,COUNTIF('O3'!A:A,A18)>0,COUNTIF('PM10'!A:A,A18)>0,COUNTIF('SO2'!A:A,A18)>0,COUNTIF(Kendaraan!A:A,A18)>0) -> TRUE
A19: 45392 | B19: 9.4 | C19: 16.73 | D19: 13.19 | E19: 9.66 | F19: 14.6 | G19: 2537 | H19: 24 | I19: =AND(COUNTIF(CO!A:A,A19)>0,COUNTIF('NO2'!A:A,A19)>0,COUNTIF('O3'!A:A,A19)>0,COUNTIF('PM10'!A:A,A19)>0,COUNTIF('SO2'!A:A,A19)>0,COUNTIF(Kendaraan!A:A,A19)>0) -> TRUE
A20: 45393 | B20: 9.31 | C20: 10.35 | D20: 9.57 | E20: 9.44 | F20: 9.84 | G20: 0.272 | H20: 24 | I20: =AND(COUNTIF(CO!A:A,A20)>0,COUNTIF('NO2'!A:A,A20)>0,COUNTIF('O3'!A:A,A20)>0,COUNTIF('PM10'!A:A,A20)>0,COUNTIF('SO2'!A:A,A20)>0,COUNTIF(Kendaraan!A:A,A20)>0) -> TRUE
A21: 45394 | B21: 10.48 | C21: 16.27 | D21: 11.07 | E21: 10.54 | F21: 14.76 | G21: 2193 | H21: 24 | I21: =AND(COUNTIF(CO!A:A,A21)>0,COUNTIF('NO2'!A:A,A21)>0,COUNTIF('O3'!A:A,A21)>0,COUNTIF('PM10'!A:A,A21)>0,COUNTIF('SO2'!A:A,A21)>0,COUNTIF(Kendaraan!A:A,A21)>0) -> TRUE
A22: 45395 | B22: 15.31 | C22: 17.79 | D22: 16.87 | E22: 15.99 | F22: 17.17 | G22: 0.717 | H22: 24 | I22: =AND(COUNTIF(CO!A:A,A22)>0,COUNTIF('NO2'!A:A,A22)>0,COUNTIF('O3'!A:A,A22)>0,COUNTIF('PM10'!A:A,A22)>0,COUNTIF('SO2'!A:A,A22)>0,COUNTIF(Kendaraan!A:A,A22)>0) -> TRUE
A23: 45396 | B23: 15.42 | C23: 18.1 | D23: 17.84 | E23: 17.57 | F23: 17.94 | G23: 0.673 | H23: 24 | I23: =AND(COUNTIF(CO!A:A,A23)>0,COUNTIF('NO2'!A:A,A23)>0,COUNTIF('O3'!A:A,A23)>0,COUNTIF('PM10'!A:A,A23)>0,COUNTIF('SO2'!A:A,A23)>0,COUNTIF(Kendaraan!A:A,A23)>0) -> TRUE
A24: 45397 | B24: 17.02 | C24: 20.98 | D24: 18.48 | E24: 17.23 | F24: 20.19 | G24: 1.47 | H24: 24 | I24: =AND(COUNTIF(CO!A:A,A24)>0,COUNTIF('NO2'!A:A,A24)>0,COUNTIF('O3'!A:A,A24)>0,COUNTIF('PM10'!A:A,A24)>0,COUNTIF('SO2'!A:A,A24)>0,COUNTIF(Kendaraan!A:A,A24)>0) -> TRUE
A25: 45398 | B25: 17.48 | C25: 21.23 | D25: 19.71 | E25: 18.89 | F25: 20.13 | G25: 0.943 | H25: 24 | I25: =AND(COUNTIF(CO!A:A,A25)>0,COUNTIF('NO2'!A:A,A25)>0,COUNTIF('O3'!A:A,A25)>0,COUNTIF('PM10'!A:A,A25)>0,COUNTIF('SO2'!A:A,A25)>0,COUNTIF(Kendaraan!A:A,A25)>0) -> TRUE
A26: 45399 | B26: 11.42 | C26: 17.1 | D26: 13.86 | E26: 12.25 | F26: 14.93 | G26: 1625 | H26: 24 | I26: =AND(COUNTIF(CO!A:A,A26)>0,COUNTIF('NO2'!A:A,A26)>0,COUNTIF('O3'!A:A,A26)>0,COUNTIF('PM10'!A:A,A26)>0,COUNTIF('SO2'!A:A,A26)>0,COUNTIF(Kendaraan!A:A,A26)>0) -> TRUE
A27: 45400 | B27: 13.31 | C27: 17.42 | D27: 15.8 | E27: 15.42 | F27: 16.44 | G27: 1116 | H27: 24 | I27: =AND(COUNTIF(CO!A:A,A27)>0,COUNTIF('NO2'!A:A,A27)>0,COUNTIF('O3'!A:A,A27)>0,COUNTIF('PM10'!A:A,A27)>0,COUNTIF('SO2'!A:A,A27)>0,COUNTIF(Kendaraan!A:A,A27)>0) -> TRUE
A28: 45401 | B28: 9.5 | C28: 13.58 | D28: 11.38 | E28: 9.94 | F28: 12.34 | G28: 1383 | H28: 24 | I28: =AND(COUNTIF(CO!A:A,A28)>0,COUNTIF('NO2'!A:A,A28)>0,COUNTIF('O3'!A:A,A28)>0,COUNTIF('PM10'!A:A,A28)>0,COUNTIF('SO2'!A:A,A28)>0,COUNTIF(Kendaraan!A:A,A28)>0) -> TRUE
A29: 45402 | B29: 10.35 | C29: 19.75 | D29: 16.03 | E29: 12.56 | F29: 18.1 | G29: 2938 | H29: 24 | I29: =AND(COUNTIF(CO!A:A,A29)>0,COUNTIF('NO2'!A:A,A29)>0,COUNTIF('O3'!A:A,A29)>0,COUNTIF('PM10'!A:A,A29)>0,COUNTIF('SO2'!A:A,A29)>0,COUNTIF(Kendaraan!A:A,A29)>0) -> TRUE
A30: 45403 | B30: 18.07 | C30: 22.69 | D30: 19.78 | E30: 19.19 | F30: 22.12 | G30: 1503 | H30: 24 | I30: =AND(COUNTIF(CO!A:A,A30)>0,COUNTIF('NO2'!A:A,A30)>0,COUNTIF('O3'!A:A,A30)>0,COUNTIF('PM10'!A:A,A30)>0,COUNTIF('SO2'!A:A,A30)>0,COUNTIF(Kendaraan!A:A,A30)>0) -> TRUE
A31: 45404 | B31: 12.1 | C31: 17.82 | D31: 13.21 | E31: 12.91 | F31: 13.5 | G31: 1522 | H31: 24 | I31: =AND(COUNTIF(CO!A:A,A31)>0,COUNTIF('NO2'!A:A,A31)>0,COUNTIF('O3'!A:A,A31)>0,COUNTIF('PM10'!A:A,A31)>0,COUNTIF('SO2'!A:A,A31)>0,COUNTIF(Kendaraan!A:A,A31)>0) -> TRUE
A32: 45405 | B32: 13.06 | C32: 20.71 | D32: 14.8 | E32: 14.18 | F32: 15.82 | G32: 1.88 | H32: 24 | I32: =AND(COUNTIF(CO!A:A,A32)>0,COUNTIF('NO2'!A:A,A32)>0,COUNTIF('O3'!A:A,A32)>0,COUNTIF('PM10'!A:A,A32)>0,COUNTIF('SO2'!A:A,A32)>0,COUNTIF(Kendaraan!A:A,A32)>0) -> TRUE
A33: 45406 | B33: 22.04 | C33: 32.1 | D33: 29.65 | E33: 27.97 | F33: 30.95 | G33: 2511 | H33: 24 | I33: =AND(COUNTIF(CO!A:A,A33)>0,COUNTIF('NO2'!A:A,A33)>0,COUNTIF('O3'!A:A,A33)>0,COUNTIF('PM10'!A:A,A33)>0,COUNTIF('SO2'!A:A,A33)>0,COUNTIF(Kendaraan!A:A,A33)>0) -> TRUE
A34: 45407 | B34: 25.88 | C34: 29.73 | D34: 28.45 | E34: 27.97 | F34: 28.84 | G34: 0.855 | H34: 24 | I34: =AND(COUNTIF(CO!A:A,A34)>0,COUNTIF('NO2'!A:A,A34)>0,COUNTIF('O3'!A:A,A34)>0,COUNTIF('PM10'!A:A,A34)>0,COUNTIF('SO2'!A:A,A34)>0,COUNTIF(Kendaraan!A:A,A34)>0) -> TRUE
A35: 45408 | B35: 20.21 | C35: 25.21 | D35: 21.33 | E35: 20.72 | F35: 22.37 | G35: 1461 | H35: 24 | I35: =AND(COUNTIF(CO!A:A,A35)>0,COUNTIF('NO2'!A:A,A35)>0,COUNTIF('O3'!A:A,A35)>0,COUNTIF('PM10'!A:A,A35)>0,COUNTIF('SO2'!A:A,A35)>0,COUNTIF(Kendaraan!A:A,A35)>0) -> TRUE
A36: 45409 | B36: 15.69 | C36: 24.79 | D36: 17.57 | E36: 17.17 | F36: 20.36 | G36: 2364 | H36: 24 | I36: =AND(COUNTIF(CO!A:A,A36)>0,COUNTIF('NO2'!A:A,A36)>0,COUNTIF('O3'!A:A,A36)>0,COUNTIF('PM10'!A:A,A36)>0,COUNTIF('SO2'!A:A,A36)>0,COUNTIF(Kendaraan!A:A,A36)>0) -> TRUE
A37: 45410 | B37: 25.67 | C37: 31.35 | D37: 28.6 | E37: 27.22 | F37: 29.96 | G37: 1616 | H37: 24 | I37: =AND(COUNTIF(CO!A:A,A37)>0,COUNTIF('NO2'!A:A,A37)>0,COUNTIF('O3'!A:A,A37)>0,COUNTIF('PM10'!A:A,A37)>0,COUNTIF('SO2'!A:A,A37)>0,COUNTIF(Kendaraan!A:A,A37)>0) -> TRUE
A38: 45411 | B38: 24 | C38: 28.33 | D38: 26.11 | E38: 25.49 | F38: 27.67 | G38: 1301 | H38: 24 | I38: =AND(COUNTIF(CO!A:A,A38)>0,COUNTIF('NO2'!A:A,A38)>0,COUNTIF('O3'!A:A,A38)>0,COUNTIF('PM10'!A:A,A38)>0,COUNTIF('SO2'!A:A,A38)>0,COUNTIF(Kendaraan!A:A,A38)>0) -> TRUE
A39: 45412 | B39: 27.9 | C39: 32.79 | D39: 31.49 | E39: 28.93 | F39: 32.38 | G39: 1758 | H39: 24 | I39: =AND(COUNTIF(CO!A:A,A39)>0,COUNTIF('NO2'!A:A,A39)>0,COUNTIF('O3'!A:A,A39)>0,COUNTIF('PM10'!A:A,A39)>0,COUNTIF('SO2'!A:A,A39)>0,COUNTIF(Kendaraan!A:A,A39)>0) -> TRUE
A40: 45413 | B40: 26.56 | C40: 33.72 | D40: 29.73 | E40: 27.69 | F40: 32.94 | G40: 2518 | H40: 24 | I40: =AND(COUNTIF(CO!A:A,A40)>0,COUNTIF('NO2'!A:A,A40)>0,COUNTIF('O3'!A:A,A40)>0,COUNTIF('PM10'!A:A,A40)>0,COUNTIF('SO2'!A:A,A40)>0,COUNTIF(Kendaraan!A:A,A40)>0) -> TRUE
...

Sheet SO2
A1: date | B1: min | C1: max | D1: median | E1: q1 | F1: q3 | G1: stdev | H1: count | I1: cek
A2: 45337 | B2: 36 | C2: 41.12 | D2: 39.89 | E2: 38.92 | F2: 40.71 | G2: 1375 | H2: 24 | I2: =AND(COUNTIF(CO!A:A,A2)>0,COUNTIF('NO2'!A:A,A2)>0,COUNTIF('O3'!A:A,A2)>0,COUNTIF('PM10'!A:A,A2)>0,COUNTIF('PM2.5'!A:A,A2)>0,COUNTIF(Kendaraan!A:A,A2)>0) -> TRUE
A3: 45338 | B3: 35.83 | C3: 64.75 | D3: 44.29 | E3: 39.58 | F3: 53.52 | G3: 8643 | H3: 24 | I3: =AND(COUNTIF(CO!A:A,A3)>0,COUNTIF('NO2'!A:A,A3)>0,COUNTIF('O3'!A:A,A3)>0,COUNTIF('PM10'!A:A,A3)>0,COUNTIF('PM2.5'!A:A,A3)>0,COUNTIF(Kendaraan!A:A,A3)>0) -> TRUE
A4: 45342 | B4: 0.04 | C4: 49.35 | D4: 18.2 | E4: 4.51 | F4: 34.46 | G4: 16234 | H4: 24 | I4: =AND(COUNTIF(CO!A:A,A4)>0,COUNTIF('NO2'!A:A,A4)>0,COUNTIF('O3'!A:A,A4)>0,COUNTIF('PM10'!A:A,A4)>0,COUNTIF('PM2.5'!A:A,A4)>0,COUNTIF(Kendaraan!A:A,A4)>0) -> TRUE
A5: 45343 | B5: 52.06 | C5: 76 | D5: 68.34 | E5: 64.06 | F5: 72.34 | G5: 6296 | H5: 24 | I5: =AND(COUNTIF(CO!A:A,A5)>0,COUNTIF('NO2'!A:A,A5)>0,COUNTIF('O3'!A:A,A5)>0,COUNTIF('PM10'!A:A,A5)>0,COUNTIF('PM2.5'!A:A,A5)>0,COUNTIF(Kendaraan!A:A,A5)>0) -> TRUE
A6: 45344 | B6: 76.67 | C6: 81 | D6: 81 | E6: 80.34 | F6: 81 | G6: 1282 | H6: 24 | I6: =AND(COUNTIF(CO!A:A,A6)>0,COUNTIF('NO2'!A:A,A6)>0,COUNTIF('O3'!A:A,A6)>0,COUNTIF('PM10'!A:A,A6)>0,COUNTIF('PM2.5'!A:A,A6)>0,COUNTIF(Kendaraan!A:A,A6)>0) -> TRUE
A7: 45372 | B7: 18.35 | C7: 18.79 | D7: 18.69 | E7: 18.51 | F7: 18.76 | G7: 0.145 | H7: 9 | I7: =AND(COUNTIF(CO!A:A,A7)>0,COUNTIF('NO2'!A:A,A7)>0,COUNTIF('O3'!A:A,A7)>0,COUNTIF('PM10'!A:A,A7)>0,COUNTIF('PM2.5'!A:A,A7)>0,COUNTIF(Kendaraan!A:A,A7)>0) -> TRUE
A8: 45373 | B8: 21.4 | C8: 21.46 | D8: 21.42 | E8: 21.41 | F8: 21.44 | G8: 0.022 | H8: 4 | I8: =AND(COUNTIF(CO!A:A,A8)>0,COUNTIF('NO2'!A:A,A8)>0,COUNTIF('O3'!A:A,A8)>0,COUNTIF('PM10'!A:A,A8)>0,COUNTIF('PM2.5'!A:A,A8)>0,COUNTIF(Kendaraan!A:A,A8)>0) -> TRUE
A9: 45377 | B9: 17.46 | C9: 17.46 | D9: 17.46 | E9: 17.46 | F9: 17.46 | G9: 0 | H9: 1 | I9: =AND(COUNTIF(CO!A:A,A9)>0,COUNTIF('NO2'!A:A,A9)>0,COUNTIF('O3'!A:A,A9)>0,COUNTIF('PM10'!A:A,A9)>0,COUNTIF('PM2.5'!A:A,A9)>0,COUNTIF(Kendaraan!A:A,A9)>0) -> TRUE
A10: 45383 | B10: 19.35 | C10: 23.44 | D10: 20.17 | E10: 19.6 | F10: 21.88 | G10: 1244 | H10: 21 | I10: =AND(COUNTIF(CO!A:A,A10)>0,COUNTIF('NO2'!A:A,A10)>0,COUNTIF('O3'!A:A,A10)>0,COUNTIF('PM10'!A:A,A10)>0,COUNTIF('PM2.5'!A:A,A10)>0,COUNTIF(Kendaraan!A:A,A10)>0) -> TRUE
A11: 45384 | B11: 23.19 | C11: 25.19 | D11: 24.49 | E11: 24.14 | F11: 24.73 | G11: 0.46 | H11: 24 | I11: =AND(COUNTIF(CO!A:A,A11)>0,COUNTIF('NO2'!A:A,A11)>0,COUNTIF('O3'!A:A,A11)>0,COUNTIF('PM10'!A:A,A11)>0,COUNTIF('PM2.5'!A:A,A11)>0,COUNTIF(Kendaraan!A:A,A11)>0) -> TRUE
A12: 45385 | B12: 20.29 | C12: 22.94 | D12: 22.4 | E12: 20.92 | F12: 22.7 | G12: 0.902 | H12: 24 | I12: =AND(COUNTIF(CO!A:A,A12)>0,COUNTIF('NO2'!A:A,A12)>0,COUNTIF('O3'!A:A,A12)>0,COUNTIF('PM10'!A:A,A12)>0,COUNTIF('PM2.5'!A:A,A12)>0,COUNTIF(Kendaraan!A:A,A12)>0) -> TRUE
